Workbook

Sheet Resumen
A1: Resumen de escenarios - plan de deuda
A2: Todo se recalcula desde la hoja Supuestos. Cambia Meta/Actual, alquiler o plazo allí.
A4: Indicador | B4: A1 Préstamo + solo cuota | C4: A2 Préstamo + prepagos | D4: B Sin préstamo
A5: Mes en que quedas sin deuda | B5: =IFERROR(INDEX('A1 Préstamo + solo cuota'!$A$8:$A$34,MATCH(1,'A1 Préstamo + solo cuota'!$AG$8:$AG$34,0)),"Después de dic-28") | C5: =IFERROR(INDEX('A2 Préstamo + prepagos'!$A$8:$A$34,MATCH(1,'A2 Préstamo + prepagos'!$AG$8:$AG$34,0)),"Después de dic-28") | D5: =IFERROR(INDEX('B Sin préstamo'!$A$8:$A$34,MATCH(1,'B Sin préstamo'!$AG$8:$AG$34,0)),"Después de dic-28")
A6: Intereses + seguros pagados (total) | B6: =SUMPRODUCT(('A1 Préstamo + solo cuota'!$A$8:$A$34<=IFERROR(INDEX('A1 Préstamo + solo cuota'!$A$8:$A$34,MATCH(1,'A1 Préstamo + solo cuota'!$AG$8:$AG$34,0)),DATE(2028,12,1)))*'A1 Préstamo + solo cuota'!$AE$8:$AE$34) | C6: =SUMPRODUCT(('A2 Préstamo + prepagos'!$A$8:$A$34<=IFERROR(INDEX('A2 Préstamo + prepagos'!$A$8:$A$34,MATCH(1,'A2 Préstamo + prepagos'!$AG$8:$AG$34,0)),DATE(2028,12,1)))*'A2 Préstamo + prepagos'!$AE$8:$AE$34) | D6: =SUMPRODUCT(('B Sin préstamo'!$A$8:$A$34<=IFERROR(INDEX('B Sin préstamo'!$A$8:$A$34,MATCH(1,'B Sin préstamo'!$AG$8:$AG$34,0)),DATE(2028,12,1)))*'B Sin préstamo'!$AE$8:$AE$34)
A7: Deuda total a dic-26 | B7: =INDEX('A1 Préstamo + solo cuota'!$AD$8:$AD$34,MATCH(DATE(2026,12,1),'A1 Préstamo + solo cuota'!$A$8:$A$34,0)) | C7: =INDEX('A2 Préstamo + prepagos'!$AD$8:$AD$34,MATCH(DATE(2026,12,1),'A2 Préstamo + prepagos'!$A$8:$A$34,0)) | D7: =INDEX('B Sin préstamo'!$AD$8:$AD$34,MATCH(DATE(2026,12,1),'B Sin préstamo'!$A$8:$A$34,0))
A8: Ahorro acumulado a dic-26 | B8: =INDEX('A1 Préstamo + solo cuota'!$AC$8:$AC$34,MATCH(DATE(2026,12,1),'A1 Préstamo + solo cuota'!$A$8:$A$34,0)) | C8: =INDEX('A2 Préstamo + prepagos'!$AC$8:$AC$34,MATCH(DATE(2026,12,1),'A2 Préstamo + prepagos'!$A$8:$A$34,0)) | D8: =INDEX('B Sin préstamo'!$AC$8:$AC$34,MATCH(DATE(2026,12,1),'B Sin préstamo'!$A$8:$A$34,0))
A9: Deuda total a dic-27 | B9: =INDEX('A1 Préstamo + solo cuota'!$AD$8:$AD$34,MATCH(DATE(2027,12,1),'A1 Préstamo + solo cuota'!$A$8:$A$34,0)) | C9: =INDEX('A2 Préstamo + prepagos'!$AD$8:$AD$34,MATCH(DATE(2027,12,1),'A2 Préstamo + prepagos'!$A$8:$A$34,0)) | D9: =INDEX('B Sin préstamo'!$AD$8:$AD$34,MATCH(DATE(2027,12,1),'B Sin préstamo'!$A$8:$A$34,0))
A10: Ahorro acumulado a dic-27 | B10: =INDEX('A1 Préstamo + solo cuota'!$AC$8:$AC$34,MATCH(DATE(2027,12,1),'A1 Préstamo + solo cuota'!$A$8:$A$34,0)) | C10: =INDEX('A2 Préstamo + prepagos'!$AC$8:$AC$34,MATCH(DATE(2027,12,1),'A2 Préstamo + prepagos'!$A$8:$A$34,0)) | D10: =INDEX('B Sin préstamo'!$AC$8:$AC$34,MATCH(DATE(2027,12,1),'B Sin préstamo'!$A$8:$A$34,0))
A11: Patrimonio neto a dic-27 (ahorro - deuda) | B11: =B10-B9 | C11: =C10-C9 | D11: =D10-D9
A12: Ahorro acumulado a dic-28 | B12: =INDEX('A1 Préstamo + solo cuota'!$AC$8:$AC$34,MATCH(DATE(2028,12,1),'A1 Préstamo + solo cuota'!$A$8:$A$34,0)) | C12: =INDEX('A2 Préstamo + prepagos'!$AC$8:$AC$34,MATCH(DATE(2028,12,1),'A2 Préstamo + prepagos'!$A$8:$A$34,0)) | D12: =INDEX('B Sin préstamo'!$AC$8:$AC$34,MATCH(DATE(2028,12,1),'B Sin préstamo'!$A$8:$A$34,0))
A13: Meses con déficit (ahorro del mes < 0) | B13: =COUNTIF('A1 Préstamo + solo cuota'!$AB$8:$AB$34,"<-0.01") | C13: =COUNTIF('A2 Préstamo + prepagos'!$AB$8:$AB$34,"<-0.01") | D13: =COUNTIF('B Sin préstamo'!$AB$8:$AB$34,"<-0.01")
A16: Deuda total por mes
A17: Mes | B17: A1 Préstamo + solo cuota | C17: A2 Préstamo + prepagos | D17: B Sin préstamo
A18: ='A1 Préstamo + solo cuota'!A8 | B18: ='A1 Préstamo + solo cuota'!AD8 | C18: ='A2 Préstamo + prepagos'!AD8 | D18: ='B Sin préstamo'!AD8
A19: ='A1 Préstamo + solo cuota'!A9 | B19: ='A1 Préstamo + solo cuota'!AD9 | C19: ='A2 Préstamo + prepagos'!AD9 | D19: ='B Sin préstamo'!AD9
A20: ='A1 Préstamo + solo cuota'!A10 | B20: ='A1 Préstamo + solo cuota'!AD10 | C20: ='A2 Préstamo + prepagos'!AD10 | D20: ='B Sin préstamo'!AD10
A21: ='A1 Préstamo + solo cuota'!A11 | B21: ='A1 Préstamo + solo cuota'!AD11 | C21: ='A2 Préstamo + prepagos'!AD11 | D21: ='B Sin préstamo'!AD11
A22: ='A1 Préstamo + solo cuota'!A12 | B22: ='A1 Préstamo + solo cuota'!AD12 | C22: ='A2 Préstamo + prepagos'!AD12 | D22: ='B Sin préstamo'!AD12
A23: ='A1 Préstamo + solo cuota'!A13 | B23: ='A1 Préstamo + solo cuota'!AD13 | C23: ='A2 Préstamo + prepagos'!AD13 | D23: ='B Sin préstamo'!AD13
A24: ='A1 Préstamo + solo cuota'!A14 | B24: ='A1 Préstamo + solo cuota'!AD14 | C24: ='A2 Préstamo + prepagos'!AD14 | D24: ='B Sin préstamo'!AD14
A25: ='A1 Préstamo + solo cuota'!A15 | B25: ='A1 Préstamo + solo cuota'!AD15 | C25: ='A2 Préstamo + prepagos'!AD15 | D25: ='B Sin préstamo'!AD15
A26: ='A1 Préstamo + solo cuota'!A16 | B26: ='A1 Préstamo + solo cuota'!AD16 | C26: ='A2 Préstamo + prepagos'!AD16 | D26: ='B Sin préstamo'!AD16
A27: ='A1 Préstamo + solo cuota'!A17 | B27: ='A1 Préstamo + solo cuota'!AD17 | C27: ='A2 Préstamo + prepagos'!AD17 | D27: ='B Sin préstamo'!AD17
A28: ='A1 Préstamo + solo cuota'!A18 | B28: ='A1 Préstamo + solo cuota'!AD18 | C28: ='A2 Préstamo + prepagos'!AD18 | D28: ='B Sin préstamo'!AD18
A29: ='A1 Préstamo + solo cuota'!A19 | B29: ='A1 Préstamo + solo cuota'!AD19 | C29: ='A2 Préstamo + prepagos'!AD19 | D29: ='B Sin préstamo'!AD19
... A44: ='A1 Préstamo + solo cuota'!A34 | B44: ='A1 Préstamo + solo cuota'!AD34 | C44: ='A2 Préstamo + prepagos'!AD34 | D44: ='B Sin préstamo'!AD34

Sheet Supuestos
A1: Supuestos del plan de deuda
A2: Celdas en azul = datos editables. Amarillo = supuestos clave a revisar. Montos en soles.
A4: Ingresos y efectivo
A5: Fecha inicio (mes actual) | B5: 46296 | C5: Octubre 2026
A6: Ingreso neto mensual | B6: 4600 | C6: Dato del usuario (Simtryx, neto de retención 4ta)
A7: Efectivo disponible en octubre | B7: 2747 | C7: BCP 2,480 + Plin 67 + 200 servicios (dato del usuario)
A8: Gastos de octubre (mes parcial, incluye pensión) | B8: 2098 | C8: Pensión 815 + servicios 313 + super 400 + delivery/taxi 450 + otros 120
A9: Gastos mensuales
A10: Escenario de gasto (Meta / Actual) | B10: Meta | C10: Escribe Meta o Actual
A11: Pensión PUCP | B11: 815 | C11: Estado de cuenta Visa Infinite, 14-Sep
A12: Último mes de pensión | B12: 46357 | C12: Usuario: paga la universidad hasta fin de año
A13: Alquiler mensual | B13: 0 | C13: Usuario: lo demás se mantiene igual. Pon el alquiler aquí cuando lo sepas
A14: Inicio de alquiler | B14: 46388 | C14: Mudanza estimada en diciembre 2026
A15: Devolución de impuestos (estimado) | B15: 0 | C15: Posible ~S/ 4,000 en abril 2027. Confirmar con contador. En 0 por prudencia
A16: Mes de devolución | B16: 46478
A17: Tarjeta Visa Infinite
A18: Saldo tarjeta (consumido) | B18: 8992.74 | C18: App Interbank 05/10/2026, incluye cargos pendientes
A19: TEA tarjeta | B19: 0.6478 | C19: Estado de cuenta 21/09/2026
A20: Tasa seguro desgravamen tarjeta | B20: 0.004 | C20: 0.40% del saldo promedio, tope S/ 25
A21: Tope seguro tarjeta | B21: 25 | C21: Estado de cuenta
A22: ExtraCash actual (Visa Access 5293)
A23: Saldo capital después de cuota de octubre | B23: 2883.16 | C23: 3,430.10 - 546.94 de capital pagado el 01/10
A24: TEA ExtraCash actual | B24: 0.1663 | C24: Estado de cuenta préstamo
A25: Cuota sin seguro | B25: 598.24 | C25: Estado de cuenta préstamo
A26: Seguro desgravamen mensual | B26: 17.17 | C26: Estado de cuenta préstamo
A27: ExtraCash nuevo (oferta)
A28: Monto del préstamo | B28: 9000 | C28: Cubre el consumido de la tarjeta
A29: Plazo (meses: 24, 36 o 48) | B29: 24 | C29: Simulación app Interbank
A30: TEA préstamo nuevo | B30: 0.1663 | C30: Simulación app (TCEA 21.31%)
A32: Gastos mensuales por rubro (sin pensión)
A33: Rubro | B33: Meta | C33: Actual (ciclo ago-sep) | D33: Nota
A34: Supermercado | B34: 500 | C34: 483.36
A35: Delivery / comida fuera | B35: 300 | C35: 876.5 | D35: Meta acordada
A36: Taxis | B36: 300 | C36: 505.4 | D36: 44 viajes en el ciclo
A37: Otros | B37: 200 | C37: 361 | D37: Tiendas, compras, Plin, combustible
A38: Servicios (luz, gas, internet, celular) | B38: 313 | C38: 312.7
A39: Seguro Interseguro | B39: 33.5 | C39: 33.5
A40: Contador Luxr | B40: 150 | C40: 150
A41: Total | B41: =SUM(B34:B40) | C41: =SUM(C34:C40)
A43: Gasto mensual usado en el modelo | B43: =IF(Supuestos!$B$10="Actual",C41,B41)
...

Sheet A1 Préstamo + solo cuota
A1: A1 Préstamo + solo cuota
A2: Pide el préstamo, paga solo las cuotas y ahorra el sobrante.
A3: Usa préstamo nuevo (1/0) | B3: 1 | D3: Ahorro negativo = déficit: el plan no alcanza ese mes.
A4: Prepagar EC actual (1/0) | B4: 0
A5: Prepagar préstamo nuevo (1/0) | B5: 0
A7: Mes | B7: Ingreso | C7: Devolución impuestos | D7: Gastos de vida | E7: Pensión | F7: Alquiler | G7: Disponible | H7: Tarjeta saldo inicial | I7: Pagado con préstamo | J7: Interés tarjeta | K7: Seguro tarjeta | L7: Pago extra tarjeta | M7: Tarjeta saldo final | N7: EC actual saldo inicial | O7: Interés EC | P7: Seguro EC | Q7: Cuota EC | R7: Prepago EC | S7: EC saldo final | T7: Préstamo nuevo saldo inicial | U7: Desembolso | V7: Interés préstamo | W7: Seguro préstamo | X7: Cuota préstamo | Y7: Prepago préstamo | Z7: Préstamo saldo final | AA7: Pagos obligatorios | AB7: Ahorro del mes | AC7: Ahorro acumulado | AD7: Deuda total | AE7: Costo financiero del mes | AF7: Costo financiero acumulado | AG7: Libre de deuda
A8: =Supuestos!$B$5 | B8: =IF(A8=Supuestos!$B$5,Supuestos!$B$7,Supuestos!$B$6) | C8: =IF(A8=Supuestos!$B$16,Supuestos!$B$15,0) | D8: =IF(A8=Supuestos!$B$5,Supuestos!$B$8,Supuestos!$B$43) | E8: =IF(AND(A8>Supuestos!$B$5,A8<=Supuestos!$B$12),Supuestos!$B$11,0) | F8: =IF(A8>=Supuestos!$B$14,Supuestos!$B$13,0) | G8: =B8+C8-D8-E8-F8 | H8: =Supuestos!$B$18 | I8: =MIN(U8,H8) | J8: =(H8-I8)*Supuestos!$B$46 | K8: =IF(H8-I8>0.01,MIN(Supuestos!$B$21,(H8-I8)*Supuestos!$B$20),0) | L8: =MIN(MAX(G8-AA8,0),H8-I8) | M8: =H8-I8-L8 | N8: =Supuestos!$B$23 | O8: =IF(A8=Supuestos!$B$5,0,N8*Supuestos!$B$47) | P8: =IF(AND(A8>Supuestos!$B$5,N8>0.01),Supuestos!$B$26,0) | Q8: =IF(A8=Supuestos!$B$5,0,MIN(Supuestos!$B$25,N8+O8)) | R8: =$B$4*MIN(MAX(G8-AA8-L8,0),N8+O8-Q8) | S8: =N8+O8-Q8-R8 | T8: =0 | U8: =IF(A8=Supuestos!$B$5,$B$3*Supuestos!$B$28,0) | V8: =T8*Supuestos!$B$48 | W8: =IF(T8>0.01,Supuestos!$B$58,0) | X8: =MIN(Supuestos!$B$57,T8+V8) | Y8: =$B$5*MIN(MAX(G8-AA8-L8-R8,0),T8+V8-X8) | Z8: =T8+U8+V8-X8-Y8 | AA8: =J8+K8+P8+Q8+W8+X8 | AB8: =G8-AA8-L8-R8-Y8+U8-I8 | AC8: =AB8 | AD8: =M8+S8+Z8 | AE8: =J8+K8+O8+P8+V8+W8 | AF8: =AE8 | AG8: =IF(AD8<0.01,1,0)
A9: =DATE(YEAR(A8),MONTH(A8)+1,1) | B9: =IF(A9=Supuestos!$B$5,Supuestos!$B$7,Supuestos!$B$6) | C9: =IF(A9=Supuestos!$B$16,Supuestos!$B$15,0) | D9: =IF(A9=Supuestos!$B$5,Supuestos!$B$8,Supuestos!$B$43) | E9: =IF(AND(A9>Supuestos!$B$5,A9<=Supuestos!$B$12),Supuestos!$B$11,0) | F9: =IF(A9>=Supuestos!$B$14,Supuestos!$B$13,0) | G9: =B9+C9-D9-E9-F9 | H9: =M8 | I9: =MIN(U9,H9) | J9: =(H9-I9)*Supuestos!$B$46 | K9: =IF(H9-I9>0.01,MIN(Supuestos!$B$21,(H9-I9)*Supuestos!$B$20),0) | L9: =MIN(MAX(G9-AA9,0),H9-I9) | M9: =H9-I9-L9 | N9: =S8 | O9: =IF(A9=Supuestos!$B$5,0,N9*Supuestos!$B$47) | P9: =IF(AND(A9>Supuestos!$B$5,N9>0.01),Supuestos!$B$26,0) | Q9: =IF(A9=Supuestos!$B$5,0,MIN(Supuestos!$B$25,N9+O9)) | R9: =$B$4*MIN(MAX(G9-AA9-L9,0),N9+O9-Q9) | S9: =N9+O9-Q9-R9 | T9: =Z8 | U9: =IF(A9=Supuestos!$B$5,$B$3*Supuestos!$B$28,0) | V9: =T9*Supuestos!$B$48 | W9: =IF(T9>0.01,Supuestos!$B$58,0) | X9: =MIN(Supuestos!$B$57,T9+V9) | Y9: =$B$5*MIN(MAX(G9-AA9-L9-R9,0),T9+V9-X9) | Z9: =T9+U9+V9-X9-Y9 | AA9: =J9+K9+P9+Q9+W9+X9 | AB9: =G9-AA9-L9-R9-Y9+U9-I9 | AC9: =AC8+AB9 | AD9: =M9+S9+Z9 | AE9: =J9+K9+O9+P9+V9+W9 | AF9: =AF8+AE9 | AG9: =IF(AD9<0.01,1,0)
A10: =DATE(YEAR(A9),MONTH(A9)+1,1) | B10: =IF(A10=Supuestos!$B$5,Supuestos!$B$7,Supuestos!$B$6) | C10: =IF(A10=Supuestos!$B$16,Supuestos!$B$15,0) | D10: =IF(A10=Supuestos!$B$5,Supuestos!$B$8,Supuestos!$B$43) | E10: =IF(AND(A10>Supuestos!$B$5,A10<=Supuestos!$B$12),Supuestos!$B$11,0) | F10: =IF(A10>=Supuestos!$B$14,Supuestos!$B$13,0) | G10: =B10+C10-D10-E10-F10 | H10: =M9 | I10: =MIN(U10,H10) | J10: =(H10-I10)*Supuestos!$B$46 | K10: =IF(H10-I10>0.01,MIN(Supuestos!$B$21,(H10-I10)*Supuestos!$B$20),0) | L10: =MIN(MAX(G10-AA10,0),H10-I10) | M10: =H10-I10-L10 | N10: =S9 | O10: =IF(A10=Supuestos!$B$5,0,N10*Supuestos!$B$47) | P10: =IF(AND(A10>Supuestos!$B$5,N10>0.01),Supuestos!$B$26,0) | Q10: =IF(A10=Supuestos!$B$5,0,MIN(Supuestos!$B$25,N10+O10)) | R10: =$B$4*MIN(MAX(G10-AA10-L10,0),N10+O10-Q10) | S10: =N10+O10-Q10-R10 | T10: =Z9 | U10: =IF(A10=Supuestos!$B$5,$B$3*Supuestos!$B$28,0) | V10: =T10*Supuestos!$B$48 | W10: =IF(T10>0.01,Supuestos!$B$58,0) | X10: =MIN(Supuestos!$B$57,T10+V10) | Y10: =$B$5*MIN(MAX(G10-AA10-L10-R10,0),T10+V10-X10) | Z10: =T10+U10+V10-X10-Y10 | AA10: =J10+K10+P10+Q10+W10+X10 | AB10: =G10-AA10-L10-R10-Y10+U10-I10 | AC10: =AC9+AB10 | AD10: =M10+S10+Z10 | AE10: =J10+K10+O10+P10+V10+W10 | AF10: =AF9+AE10 | AG10: =IF(AD10<0.01,1,0)
A11: =DATE(YEAR(A10),MONTH(A10)+1,1) | B11: =IF(A11=Supuestos!$B$5,Supuestos!$B$7,Supuestos!$B$6) | C11: =IF(A11=Supuestos!$B$16,Supuestos!$B$15,0) | D11: =IF(A11=Supuestos!$B$5,Supuestos!$B$8,Supuestos!$B$43) | E11: =IF(AND(A11>Supuestos!$B$5,A11<=Supuestos!$B$12),Supuestos!$B$11,0) | F11: =IF(A11>=Supuestos!$B$14,Supuestos!$B$13,0) | G11: =B11+C11-D11-E11-F11 | H11: =M10 | I11: =MIN(U11,H11) | J11: =(H11-I11)*Supuestos!$B$46 | K11: =IF(H11-I11>0.01,MIN(Supuestos!$B$21,(H11-I11)*Supuestos!$B$20),0) | L11: =MIN(MAX(G11-AA11,0),H11-I11) | M11: =H11-I11-L11 | N11: =S10 | O11: =IF(A11=Supuestos!$B$5,0,N11*Supuestos!$B$47) | P11: =IF(AND(A11>Supuestos!$B$5,N11>0.01),Supuestos!$B$26,0) | Q11: =IF(A11=Supuestos!$B$5,0,MIN(Supuestos!$B$25,N11+O11)) | R11: =$B$4*MIN(MAX(G11-AA11-L11,0),N11+O11-Q11) | S11: =N11+O11-Q11-R11 | T11: =Z10 | U11: =IF(A11=Supuestos!$B$5,$B$3*Supuestos!$B$28,0) | V11: =T11*Supuestos!$B$48 | W11: =IF(T11>0.01,Supuestos!$B$58,0) | X11: =MIN(Supuestos!$B$57,T11+V11) | Y11: =$B$5*MIN(MAX(G11-AA11-L11-R11,0),T11+V11-X11) | Z11: =T11+U11+V11-X11-Y11 | AA11: =J11+K11+P11+Q11+W11+X11 | AB11: =G11-AA11-L11-R11-Y11+U11-I11 | AC11: =AC10+AB11 | AD11: =M11+S11+Z11 | AE11: =J11+K11+O11+P11+V11+W11 | AF11: =AF10+AE11 | AG11: =IF(AD11<0.01,1,0)
A12: =DATE(YEAR(A11),MONTH(A11)+1,1) | B12: =IF(A12=Supuestos!$B$5,Supuestos!$B$7,Supuestos!$B$6) | C12: =IF(A12=Supuestos!$B$16,Supuestos!$B$15,0) | D12: =IF(A12=Supuestos!$B$5,Supuestos!$B$8,Supuestos!$B$43) | E12: =IF(AND(A12>Supuestos!$B$5,A12<=Supuestos!$B$12),Supuestos!$B$11,0) | F12: =IF(A12>=Supuestos!$B$14,Supuestos!$B$13,0) | G12: =B12+C12-D12-E12-F12 | H12: =M11 | I12: =MIN(U12,H12) | J12: =(H12-I12)*Supuestos!$B$46 | K12: =IF(H12-I12>0.01,MIN(Supuestos!$B$21,(H12-I12)*Supuestos!$B$20),0) | L12: =MIN(MAX(G12-AA12,0),H12-I12) | M12: =H12-I12-L12 | N12: =S11 | O12: =IF(A12=Supuestos!$B$5,0,N12*Supuestos!$B$47) | P12: =IF(AND(A12>Supuestos!$B$5,N12>0.01),Supuestos!$B$26,0) | Q12: =IF(A12=Supuestos!$B$5,0,MIN(Supuestos!$B$25,N12+O12)) | R12: =$B$4*MIN(MAX(G12-AA12-L12,0),N12+O12-Q12) | S12: =N12+O12-Q12-R12 | T12: =Z11 | U12: =IF(A12=Supuestos!$B$5,$B$3*Supuestos!$B$28,0) | V12: =T12*Supuestos!$B$48 | W12: =IF(T12>0.01,Supuestos!$B$58,0) | X12: =MIN(Supuestos!$B$57,T12+V12) | Y12: =$B$5*MIN(MAX(G12-AA12-L12-R12,0),T12+V12-X12) | Z12: =T12+U12+V12-X12-Y12 | AA12: =J12+K12+P12+Q12+W12+X12 | AB12: =G12-AA12-L12-R12-Y12+U12-I12 | AC12: =AC11+AB12 | AD12: =M12+S12+Z12 | AE12: =J12+K12+O12+P12+V12+W12 | AF12: =AF11+AE12 | AG12: =IF(AD12<0.01,1,0)
A13: =DATE(YEAR(A12),MONTH(A12)+1,1) | B13: =IF(A13=Supuestos!$B$5,Supuestos!$B$7,Supuestos!$B$6) | C13: =IF(A13=Supuestos!$B$16,Supuestos!$B$15,0) | D13: =IF(A13=Supuestos!$B$5,Supuestos!$B$8,Supuestos!$B$43) | E13: =IF(AND(A13>Supuestos!$B$5,A13<=Supuestos!$B$12),Supuestos!$B$11,0) | F13: =IF(A13>=Supuestos!$B$14,Supuestos!$B$13,0) | G13: =B13+C13-D13-E13-F13 | H13: =M12 | I13: =MIN(U13,H13) | J13: =(H13-I13)*Supuestos!$B$46 | K13: =IF(H13-I13>0.01,MIN(Supuestos!$B$21,(H13-I13)*Supuestos!$B$20),0) | L13: =MIN(MAX(G13-AA13,0),H13-I13) | M13: =H13-I13-L13 | N13: =S12 | O13: =IF(A13=Supuestos!$B$5,0,N13*Supuestos!$B$47) | P13: =IF(AND(A13>Supuestos!$B$5,N13>0.01),Supuestos!$B$26,0) | Q13: =IF(A13=Supuestos!$B$5,0,MIN(Supuestos!$B$25,N13+O13)) | R13: =$B$4*MIN(MAX(G13-AA13-L13,0),N13+O13-Q13) | S13: =N13+O13-Q13-R13 | T13: =Z12 | U13: =IF(A13=Supuestos!$B$5,$B$3*Supuestos!$B$28,0) | V13: =T13*Supuestos!$B$48 | W13: =IF(T13>0.01,Supuestos!$B$58,0) | X13: =MIN(Supuestos!$B$57,T13+V13) | Y13: =$B$5*MIN(MAX(G13-AA13-L13-R13,0),T13+V13-X13) | Z13: =T13+U13+V13-X13-Y13 | AA13: =J13+K13+P13+Q13+W13+X13 | AB13: =G13-AA13-L13-R13-Y13+U13-I13 | AC13: =AC12+AB13 | AD13: =M13+S13+Z13 | AE13: =J13+K13+O13+P13+V13+W13 | AF13: =AF12+AE13 | AG13: =IF(AD13<0.01,1,0)
A14: =DATE(YEAR(A13),MONTH(A13)+1,1) | B14: =IF(A14=Supuestos!$B$5,Supuestos!$B$7,Supuestos!$B$6) | C14: =IF(A14=Supuestos!$B$16,Supuestos!$B$15,0) | D14: =IF(A14=Supuestos!$B$5,Supuestos!$B$8,Supuestos!$B$43) | E14: =IF(AND(A14>Supuestos!$B$5,A14<=Supuestos!$B$12),Supuestos!$B$11,0) | F14: =IF(A14>=Supuestos!$B$14,Supuestos!$B$13,0) | G14: =B14+C14-D14-E14-F14 | H14: =M13 | I14: =MIN(U14,H14) | J14: =(H14-I14)*Supuestos!$B$46 | K14: =IF(H14-I14>0.01,MIN(Supuestos!$B$21,(H14-I14)*Supuestos!$B$20),0) | L14: =MIN(MAX(G14-AA14,0),H14-I14) | M14: =H14-I14-L14 | N14: =S13 | O14: =IF(A14=Supuestos!$B$5,0,N14*Supuestos!$B$47) | P14: =IF(AND(A14>Supuestos!$B$5,N14>0.01),Supuestos!$B$26,0) | Q14: =IF(A14=Supuestos!$B$5,0,MIN(Supuestos!$B$25,N14+O14)) | R14: =$B$4*MIN(MAX(G14-AA14-L14,0),N14+O14-Q14) | S14: =N14+O14-Q14-R14 | T14: =Z13 | U14: =IF(A14=Supuestos!$B$5,$B$3*Supuestos!$B$28,0) | V14: =T14*Supuestos!$B$48 | W14: =IF(T14>0.01,Supuestos!$B$58,0) | X14: =MIN(Supuestos!$B$57,T14+V14) | Y14: =$B$5*MIN(MAX(G14-AA14-L14-R14,0),T14+V14-X14) | Z14: =T14+U14+V14-X14-Y14 | AA14: =J14+K14+P14+Q14+W14+X14 | AB14: =G14-AA14-L14-R14-Y14+U14-I14 | AC14: =AC13+AB14 | AD14: =M14+S14+Z14 | AE14: =J14+K14+O14+P14+V14+W14 | AF14: =AF13+AE14 | AG14: =IF(AD14<0.01,1,0)
A15: =DATE(YEAR(A14),MONTH(A14)+1,1) | B15: =IF(A15=Supuestos!$B$5,Supuestos!$B$7,Supuestos!$B$6) | C15: =IF(A15=Supuestos!$B$16,Supuestos!$B$15,0) | D15: =IF(A15=Supuestos!$B$5,Supuestos!$B$8,Supuestos!$B$43) | E15: =IF(AND(A15>Supuestos!$B$5,A15<=Supuestos!$B$12),Supuestos!$B$11,0) | F15: =IF(A15>=Supuestos!$B$14,Supuestos!$B$13,0) | G15: =B15+C15-D15-E15-F15 | H15: =M14 | I15: =MIN(U15,H15) | J15: =(H15-I15)*Supuestos!$B$46 | K15: =IF(H15-I15>0.01,MIN(Supuestos!$B$21,(H15-I15)*Supuestos!$B$20),0) | L15: =MIN(MAX(G15-AA15,0),H15-I15) | M15: =H15-I15-L15 | N15: =S14 | O15: =IF(A15=Supuestos!$B$5,0,N15*Supuestos!$B$47) | P15: =IF(AND(A15>Supuestos!$B$5,N15>0.01),Supuestos!$B$26,0) | Q15: =IF(A15=Supuestos!$B$5,0,MIN(Supuestos!$B$25,N15+O15)) | R15: =$B$4*MIN(MAX(G15-AA15-L15,0),N15+O15-Q15) | S15: =N15+O15-Q15-R15 | T15: =Z14 | U15: =IF(A15=Supuestos!$B$5,$B$3*Supuestos!$B$28,0) | V15: =T15*Supuestos!$B$48 | W15: =IF(T15>0.01,Supuestos!$B$58,0) | X15: =MIN(Supuestos!$B$57,T15+V15) | Y15: =$B$5*MIN(MAX(G15-AA15-L15-R15,0),T15+V15-X15) | Z15: =T15+U15+V15-X15-Y15 | AA15: =J15+K15+P15+Q15+W15+X15 | AB15: =G15-AA15-L15-R15-Y15+U15-I15 | AC15: =AC14+AB15 | AD15: =M15+S15+Z15 | AE15: =J15+K15+O15+P15+V15+W15 | AF15: =AF14+AE15 | AG15: =IF(AD15<0.01,1,0)
A16: =DATE(YEAR(A15),MONTH(A15)+1,1) | B16: =IF(A16=Supuestos!$B$5,Supuestos!$B$7,Supuestos!$B$6) | C16: =IF(A16=Supuestos!$B$16,Supuestos!$B$15,0) | D16: =IF(A16=Supuestos!$B$5,Supuestos!$B$8,Supuestos!$B$43) | E16: =IF(AND(A16>Supuestos!$B$5,A16<=Supuestos!$B$12),Supuestos!$B$11,0) | F16: =IF(A16>=Supuestos!$B$14,Supuestos!$B$13,0) | G16: =B16+C16-D16-E16-F16 | H16: =M15 | I16: =MIN(U16,H16) | J16: =(H16-I16)*Supuestos!$B$46 | K16: =IF(H16-I16>0.01,MIN(Supuestos!$B$21,(H16-I16)*Supuestos!$B$20),0) | L16: =MIN(MAX(G16-AA16,0),H16-I16) | M16: =H16-I16-L16 | N16: =S15 | O16: =IF(A16=Supuestos!$B$5,0,N16*Supuestos!$B$47) | P16: =IF(AND(A16>Supuestos!$B$5,N16>0.01),Supuestos!$B$26,0) | Q16: =IF(A16=Supuestos!$B$5,0,MIN(Supuestos!$B$25,N16+O16)) | R16: =$B$4*MIN(MAX(G16-AA16-L16,0),N16+O16-Q16) | S16: =N16+O16-Q16-R16 | T16: =Z15 | U16: =IF(A16=Supuestos!$B$5,$B$3*Supuestos!$B$28,0) | V16: =T16*Supuestos!$B$48 | W16: =IF(T16>0.01,Supuestos!$B$58,0) | X16: =MIN(Supuestos!$B$57,T16+V16) | Y16: =$B$5*MIN(MAX(G16-AA16-L16-R16,0),T16+V16-X16) | Z16: =T16+U16+V16-X16-Y16 | AA16: =J16+K16+P16+Q16+W16+X16 | AB16: =G16-AA16-L16-R16-Y16+U16-I16 | AC16: =AC15+AB16 | AD16: =M16+S16+Z16 | AE16: =J16+K16+O16+P16+V16+W16 | AF16: =AF15+AE16 | AG16: =IF(AD16<0.01,1,0)
A17: =DATE(YEAR(A16),MONTH(A16)+1,1) | B17: =IF(A17=Supuestos!$B$5,Supuestos!$B$7,Supuestos!$B$6) | C17: =IF(A17=Supuestos!$B$16,Supuestos!$B$15,0) | D17: =IF(A17=Supuestos!$B$5,Supuestos!$B$8,Supuestos!$B$43) | E17: =IF(AND(A17>Supuestos!$B$5,A17<=Supuestos!$B$12),Supuestos!$B$11,0) | F17: =IF(A17>=Supuestos!$B$14,Supuestos!$B$13,0) | G17: =B17+C17-D17-E17-F17 | H17: =M16 | I17: =MIN(U17,H17) | J17: =(H17-I17)*Supuestos!$B$46 | K17: =IF(H17-I17>0.01,MIN(Supuestos!$B$21,(H17-I17)*Supuestos!$B$20),0) | L17: =MIN(MAX(G17-AA17,0),H17-I17) | M17: =H17-I17-L17 | N17: =S16 | O17: =IF(A17=Supuestos!$B$5,0,N17*Supuestos!$B$47) | P17: =IF(AND(A17>Supuestos!$B$5,N17>0.01),Supuestos!$B$26,0) | Q17: =IF(A17=Supuestos!$B$5,0,MIN(Supuestos!$B$25,N17+O17)) | R17: =$B$4*MIN(MAX(G17-AA17-L17,0),N17+O17-Q17) | S17: =N17+O17-Q17-R17 | T17: =Z16 | U17: =IF(A17=Supuestos!$B$5,$B$3*Supuestos!$B$28,0) | V17: =T17*Supuestos!$B$48 | W17: =IF(T17>0.01,Supuestos!$B$58,0) | X17: =MIN(Supuestos!$B$57,T17+V17) | Y17: =$B$5*MIN(MAX(G17-AA17-L17-R17,0),T17+V17-X17) | Z17: =T17+U17+V17-X17-Y17 | AA17: =J17+K17+P17+Q17+W17+X17 | AB17: =G17-AA17-L17-R17-Y17+U17-I17 | AC17: =AC16+AB17 | AD17: =M17+S17+Z17 | AE17: =J17+K17+O17+P17+V17+W17 | AF17: =AF16+AE17 | AG17: =IF(AD17<0.01,1,0)
A18: =DATE(YEAR(A17),MONTH(A17)+1,1) | B18: =IF(A18=Supuestos!$B$5,Supuestos!$B$7,Supuestos!$B$6) | C18: =IF(A18=Supuestos!$B$16,Supuestos!$B$15,0) | D18: =IF(A18=Supuestos!$B$5,Supuestos!$B$8,Supuestos!$B$43) | E18: =IF(AND(A18>Supuestos!$B$5,A18<=Supuestos!$B$12),Supuestos!$B$11,0) | F18: =IF(A18>=Supuestos!$B$14,Supuestos!$B$13,0) | G18: =B18+C18-D18-E18-F18 | H18: =M17 | I18: =MIN(U18,H18) | J18: =(H18-I18)*Supuestos!$B$46 | K18: =IF(H18-I18>0.01,MIN(Supuestos!$B$21,(H18-I18)*Supuestos!$B$20),0) | L18: =MIN(MAX(G18-AA18,0),H18-I18) | M18: =H18-I18-L18 | N18: =S17 | O18: =IF(A18=Supuestos!$B$5,0,N18*Supuestos!$B$47) | P18: =IF(AND(A18>Supuestos!$B$5,N18>0.01),Supuestos!$B$26,0) | Q18: =IF(A18=Supuestos!$B$5,0,MIN(Supuestos!$B$25,N18+O18)) | R18: =$B$4*MIN(MAX(G18-AA18-L18,0),N18+O18-Q18) | S18: =N18+O18-Q18-R18 | T18: =Z17 | U18: =IF(A18=Supuestos!$B$5,$B$3*Supuestos!$B$28,0) | V18: =T18*Supuestos!$B$48 | W18: =IF(T18>0.01,Supuestos!$B$58,0) | X18: =MIN(Supuestos!$B$57,T18+V18) | Y18: =$B$5*MIN(MAX(G18-AA18-L18-R18,0),T18+V18-X18) | Z18: =T18+U18+V18-X18-Y18 | AA18: =J18+K18+P18+Q18+W18+X18 | AB18: =G18-AA18-L18-R18-Y18+U18-I18 | AC18: =AC17+AB18 | AD18: =M18+S18+Z18 | AE18: =J18+K18+O18+P18+V18+W18 | AF18: =AF17+AE18 | AG18: =IF(AD18<0.01,1,0)
A19: =DATE(YEAR(A18),MONTH(A18)+1,1) | B19: =IF(A19=Supuestos!$B$5,Supuestos!$B$7,Supuestos!$B$6) | C19: =IF(A19=Supuestos!$B$16,Supuestos!$B$15,0) | D19: =IF(A19=Supuestos!$B$5,Supuestos!$B$8,Supuestos!$B$43) | E19: =IF(AND(A19>Supuestos!$B$5,A19<=Supuestos!$B$12),Supuestos!$B$11,0) | F19: =IF(A19>=Supuestos!$B$14,Supuestos!$B$13,0) | G19: =B19+C19-D19-E19-F19 | H19: =M18 | I19: =MIN(U19,H19) | J19: =(H19-I19)*Supuestos!$B$46 | K19: =IF(H19-I19>0.01,MIN(Supuestos!$B$21,(H19-I19)*Supuestos!$B$20),0) | L19: =MIN(MAX(G19-AA19,0),H19-I19) | M19: =H19-I19-L19 | N19: =S18 | O19: =IF(A19=Supuestos!$B$5,0,N19*Supuestos!$B$47) | P19: =IF(AND(A19>Supuestos!$B$5,N19>0.01),Supuestos!$B$26,0) | Q19: =IF(A19=Supuestos!$B$5,0,MIN(Supuestos!$B$25,N19+O19)) | R19: =$B$4*MIN(MAX(G19-AA19-L19,0),N19+O19-Q19) | S19: =N19+O19-Q19-R19 | T19: =Z18 | U19: =IF(A19=Supuestos!$B$5,$B$3*Supuestos!$B$28,0) | V19: =T19*Supuestos!$B$48 | W19: =IF(T19>0.01,Supuestos!$B$58,0) | X19: =MIN(Supuestos!$B$57,T19+V19) | Y19: =$B$5*MIN(MAX(G19-AA19-L19-R19,0),T19+V19-X19) | Z19: =T19+U19+V19-X19-Y19 | AA19: =J19+K19+P19+Q19+W19+X19 | AB19: =G19-AA19-L19-R19-Y19+U19-I19 | AC19: =AC18+AB19 | AD19: =M19+S19+Z19 | AE19: =J19+K19+O19+P19+V19+W19 | AF19: =AF18+AE19 | AG19: =IF(AD19<0.01,1,0)
A20: =DATE(YEAR(A19),MONTH(A19)+1,1) | B20: =IF(A20=Supuestos!$B$5,Supuestos!$B$7,Supuestos!$B$6) | C20: =IF(A20=Supuestos!$B$16,Supuestos!$B$15,0) | D20: =IF(A20=Supuestos!$B$5,Supuestos!$B$8,Supuestos!$B$43) | E20: =IF(AND(A20>Supuestos!$B$5,A20<=Supuestos!$B$12),Supuestos!$B$11,0) | F20: =IF(A20>=Supuestos!$B$14,Supuestos!$B$13,0) | G20: =B20+C20-D20-E20-F20 | H20: =M19 | I20: =MIN(U20,H20) | J20: =(H20-I20)*Supuestos!$B$46 | K20: =IF(H20-I20>0.01,MIN(Supuestos!$B$21,(H20-I20)*Supuestos!$B$20),0) | L20: =MIN(MAX(G20-AA20,0),H20-I20) | M20: =H20-I20-L20 | N20: =S19 | O20: =IF(A20=Supuestos!$B$5,0,N20*Supuestos!$B$47) | P20: =IF(AND(A20>Supuestos!$B$5,N20>0.01),Supuestos!$B$26,0) | Q20: =IF(A20=Supuestos!$B$5,0,MIN(Supuestos!$B$25,N20+O20)) | R20: =$B$4*MIN(MAX(G20-AA20-L20,0),N20+O20-Q20) | S20: =N20+O20-Q20-R20 | T20: =Z19 | U20: =IF(A20=Supuestos!$B$5,$B$3*Supuestos!$B$28,0) | V20: =T20*Supuestos!$B$48 | W20: =IF(T20>0.01,Supuestos!$B$58,0) | X20: =MIN(Supuestos!$B$57,T20+V20) | Y20: =$B$5*MIN(MAX(G20-AA20-L20-R20,0),T20+V20-X20) | Z20: =T20+U20+V20-X20-Y20 | AA20: =J20+K20+P20+Q20+W20+X20 | AB20: =G20-AA20-L20-R20-Y20+U20-I20 | AC20: =AC19+AB20 | AD20: =M20+S20+Z20 | AE20: =J20+K20+O20+P20+V20+W20 | AF20: =AF19+AE20 | AG20: =IF(AD20<0.01,1,0)
... A34: =DATE(YEAR(A33),MONTH(A33)+1,1) | B34: =IF(A34=Supuestos!$B$5,Supuestos!$B$7,Supuestos!$B$6) | C34: =IF(A34=Supuestos!$B$16,Supuestos!$B$15,0) | D34: =IF(A34=Supuestos!$B$5,Supuestos!$B$8,Supuestos!$B$43) | E34: =IF(AND(A34>Supuestos!$B$5,A34<=Supuestos!$B$12),Supuestos!$B$11,0) | F34: =IF(A34>=Supuestos!$B$14,Supuestos!$B$13,0) | G34: =B34+C34-D34-E34-F34 | H34: =M33 | I34: =MIN(U34,H34) | J34: =(H34-I34)*Supuestos!$B$46 | K34: =IF(H34-I34>0.01,MIN(Supuestos!$B$21,(H34-I34)*Supuestos!$B$20),0) | L34: =MIN(MAX(G34-AA34,0),H34-I34) | M34: =H34-I34-L34 | N34: =S33 | O34: =IF(A34=Supuestos!$B$5,0,N34*Supuestos!$B$47) | P34: =IF(AND(A34>Supuestos!$B$5,N34>0.01),Supuestos!$B$26,0) | Q34: =IF(A34=Supuestos!$B$5,0,MIN(Supuestos!$B$25,N34+O34)) | R34: =$B$4*MIN(MAX(G34-AA34-L34,0),N34+O34-Q34) | S34: =N34+O34-Q34-R34 | T34: =Z33 | U34: =IF(A34=Supuestos!$B$5,$B$3*Supuestos!$B$28,0) | V34: =T34*Supuestos!$B$48 | W34: =IF(T34>0.01,Supuestos!$B$58,0) | X34: =MIN(Supuestos!$B$57,T34+V34) | Y34: =$B$5*MIN(MAX(G34-AA34-L34-R34,0),T34+V34-X34) | Z34: =T34+U34+V34-X34-Y34 | AA34: =J34+K34+P34+Q34+W34+X34 | AB34: =G34-AA34-L34-R34-Y34+U34-I34 | AC34: =AC33+AB34 | AD34: =M34+S34+Z34 | AE34: =J34+K34+O34+P34+V34+W34 | AF34: =AF33+AE34 | AG34: =IF(AD34<0.01,1,0)

Sheet A2 Préstamo + prepagos
A1: A2 Préstamo + prepagos
A2: Pide el préstamo y usa todo el sobrante para prepagar deuda.
A3: Usa préstamo nuevo (1/0) | B3: 1 | D3: Ahorro negativo = déficit: el plan no alcanza ese mes.
A4: Prepagar EC actual (1/0) | B4: 1
A5: Prepagar préstamo nuevo (1/0) | B5: 1
A7: Mes | B7: Ingreso | C7: Devolución impuestos | D7: Gastos de vida | E7: Pensión | F7: Alquiler | G7: Disponible | H7: Tarjeta saldo inicial | I7: Pagado con préstamo | J7: Interés tarjeta | K7: Seguro tarjeta | L7: Pago extra tarjeta | M7: Tarjeta saldo final | N7: EC actual saldo inicial | O7: Interés EC | P7: Seguro EC | Q7: Cuota EC | R7: Prepago EC | S7: EC saldo final | T7: Préstamo nuevo saldo inicial | U7: Desembolso | V7: Interés préstamo | W7: Seguro préstamo | X7: Cuota préstamo | Y7: Prepago préstamo | Z7: Préstamo saldo final | AA7: Pagos obligatorios | AB7: Ahorro del mes | AC7: Ahorro acumulado | AD7: Deuda total | AE7: Costo financiero del mes | AF7: Costo financiero acumulado | AG7: Libre de deuda
A8: =Supuestos!$B$5 | B8: =IF(A8=Supuestos!$B$5,Supuestos!$B$7,Supuestos!$B$6) | C8: =IF(A8=Supuestos!$B$16,Supuestos!$B$15,0) | D8: =IF(A8=Supuestos!$B$5,Supuestos!$B$8,Supuestos!$B$43) | E8: =IF(AND(A8>Supuestos!$B$5,A8<=Supuestos!$B$12),Supuestos!$B$11,0) | F8: =IF(A8>=Supuestos!$B$14,Supuestos!$B$13,0) | G8: =B8+C8-D8-E8-F8 | H8: =Supuestos!$B$18 | I8: =MIN(U8,H8) | J8: =(H8-I8)*Supuestos!$B$46 | K8: =IF(H8-I8>0.01,MIN(Supuestos!$B$21,(H8-I8)*Supuestos!$B$20),0) | L8: =MIN(MAX(G8-AA8,0),H8-I8) | M8: =H8-I8-L8 | N8: =Supuestos!$B$23 | O8: =IF(A8=Supuestos!$B$5,0,N8*Supuestos!$B$47) | P8: =IF(AND(A8>Supuestos!$B$5,N8>0.01),Supuestos!$B$26,0) | Q8: =IF(A8=Supuestos!$B$5,0,MIN(Supuestos!$B$25,N8+O8)) | R8: =$B$4*MIN(MAX(G8-AA8-L8,0),N8+O8-Q8) | S8: =N8+O8-Q8-R8 | T8: =0 | U8: =IF(A8=Supuestos!$B$5,$B$3*Supuestos!$B$28,0) | V8: =T8*Supuestos!$B$48 | W8: =IF(T8>0.01,Supuestos!$B$58,0) | X8: =MIN(Supuestos!$B$57,T8+V8) | Y8: =$B$5*MIN(MAX(G8-AA8-L8-R8,0),T8+V8-X8) | Z8: =T8+U8+V8-X8-Y8 | AA8: =J8+K8+P8+Q8+W8+X8 | AB8: =G8-AA8-L8-R8-Y8+U8-I8 | AC8: =AB8 | AD8: =M8+S8+Z8 | AE8: =J8+K8+O8+P8+V8+W8 | AF8: =AE8 | AG8: =IF(AD8<0.01,1,0)
A9: =DATE(YEAR(A8),MONTH(A8)+1,1) | B9: =IF(A9=Supuestos!$B$5,Supuestos!$B$7,Supuestos!$B$6) | C9: =IF(A9=Supuestos!$B$16,Supuestos!$B$15,0) | D9: =IF(A9=Supuestos!$B$5,Supuestos!$B$8,Supuestos!$B$43) | E9: =IF(AND(A9>Supuestos!$B$5,A9<=Supuestos!$B$12),Supuestos!$B$11,0) | F9: =IF(A9>=Supuestos!$B$14,Supuestos!$B$13,0) | G9: =B9+C9-D9-E9-F9 | H9: =M8 | I9: =MIN(U9,H9) | J9: =(H9-I9)*Supuestos!$B$46 | K9: =IF(H9-I9>0.01,MIN(Supuestos!$B$21,(H9-I9)*Supuestos!$B$20),0) | L9: =MIN(MAX(G9-AA9,0),H9-I9) | M9: =H9-I9-L9 | N9: =S8 | O9: =IF(A9=Supuestos!$B$5,0,N9*Supuestos!$B$47) | P9: =IF(AND(A9>Supuestos!$B$5,N9>0.01),Supuestos!$B$26,0) | Q9: =IF(A9=Supuestos!$B$5,0,MIN(Supuestos!$B$25,N9+O9)) | R9: =$B$4*MIN(MAX(G9-AA9-L9,0),N9+O9-Q9) | S9: =N9+O9-Q9-R9 | T9: =Z8 | U9: =IF(A9=Supuestos!$B$5,$B$3*Supuestos!$B$28,0) | V9: =T9*Supuestos!$B$48 | W9: =IF(T9>0.01,Supuestos!$B$58,0) | X9: =MIN(Supuestos!$B$57,T9+V9) | Y9: =$B$5*MIN(MAX(G9-AA9-L9-R9,0),T9+V9-X9) | Z9: =T9+U9+V9-X9-Y9 | AA9: =J9+K9+P9+Q9+W9+X9 | AB9: =G9-AA9-L9-R9-Y9+U9-I9 | AC9: =AC8+AB9 | AD9: =M9+S9+Z9 | AE9: =J9+K9+O9+P9+V9+W9 | AF9: =AF8+AE9 | AG9: =IF(AD9<0.01,1,0)
A10: =DATE(YEAR(A9),MONTH(A9)+1,1) | B10: =IF(A10=Supuestos!$B$5,Supuestos!$B$7,Supuestos!$B$6) | C10: =IF(A10=Supuestos!$B$16,Supuestos!$B$15,0) | D10: =IF(A10=Supuestos!$B$5,Supuestos!$B$8,Supuestos!$B$43) | E10: =IF(AND(A10>Supuestos!$B$5,A10<=Supuestos!$B$12),Supuestos!$B$11,0) | F10: =IF(A10>=Supuestos!$B$14,Supuestos!$B$13,0) | G10: =B10+C10-D10-E10-F10 | H10: =M9 | I10: =MIN(U10,H10) | J10: =(H10-I10)*Supuestos!$B$46 | K10: =IF(H10-I10>0.01,MIN(Supuestos!$B$21,(H10-I10)*Supuestos!$B$20),0) | L10: =MIN(MAX(G10-AA10,0),H10-I10) | M10: =H10-I10-L10 | N10: =S9 | O10: =IF(A10=Supuestos!$B$5,0,N10*Supuestos!$B$47) | P10: =IF(AND(A10>Supuestos!$B$5,N10>0.01),Supuestos!$B$26,0) | Q10: =IF(A10=Supuestos!$B$5,0,MIN(Supuestos!$B$25,N10+O10)) | R10: =$B$4*MIN(MAX(G10-AA10-L10,0),N10+O10-Q10) | S10: =N10+O10-Q10-R10 | T10: =Z9 | U10: =IF(A10=Supuestos!$B$5,$B$3*Supuestos!$B$28,0) | V10: =T10*Supuestos!$B$48 | W10: =IF(T10>0.01,Supuestos!$B$58,0) | X10: =MIN(Supuestos!$B$57,T10+V10) | Y10: =$B$5*MIN(MAX(G10-AA10-L10-R10,0),T10+V10-X10) | Z10: =T10+U10+V10-X10-Y10 | AA10: =J10+K10+P10+Q10+W10+X10 | AB10: =G10-AA10-L10-R10-Y10+U10-I10 | AC10: =AC9+AB10 | AD10: =M10+S10+Z10 | AE10: =J10+K10+O10+P10+V10+W10 | AF10: =AF9+AE10 | AG10: =IF(AD10<0.01,1,0)
A11: =DATE(YEAR(A10),MONTH(A10)+1,1) | B11: =IF(A11=Supuestos!$B$5,Supuestos!$B$7,Supuestos!$B$6) | C11: =IF(A11=Supuestos!$B$16,Supuestos!$B$15,0) | D11: =IF(A11=Supuestos!$B$5,Supuestos!$B$8,Supuestos!$B$43) | E11: =IF(AND(A11>Supuestos!$B$5,A11<=Supuestos!$B$12),Supuestos!$B$11,0) | F11: =IF(A11>=Supuestos!$B$14,Supuestos!$B$13,0) | G11: =B11+C11-D11-E11-F11 | H11: =M10 | I11: =MIN(U11,H11) | J11: =(H11-I11)*Supuestos!$B$46 | K11: =IF(H11-I11>0.01,MIN(Supuestos!$B$21,(H11-I11)*Supuestos!$B$20),0) | L11: =MIN(MAX(G11-AA11,0),H11-I11) | M11: =H11-I11-L11 | N11: =S10 | O11: =IF(A11=Supuestos!$B$5,0,N11*Supuestos!$B$47) | P11: =IF(AND(A11>Supuestos!$B$5,N11>0.01),Supuestos!$B$26,0) | Q11: =IF(A11=Supuestos!$B$5,0,MIN(Supuestos!$B$25,N11+O11)) | R11: =$B$4*MIN(MAX(G11-AA11-L11,0),N11+O11-Q11) | S11: =N11+O11-Q11-R11 | T11: =Z10 | U11: =IF(A11=Supuestos!$B$5,$B$3*Supuestos!$B$28,0) | V11: =T11*Supuestos!$B$48 | W11: =IF(T11>0.01,Supuestos!$B$58,0) | X11: =MIN(Supuestos!$B$57,T11+V11) | Y11: =$B$5*MIN(MAX(G11-AA11-L11-R11,0),T11+V11-X11) | Z11: =T11+U11+V11-X11-Y11 | AA11: =J11+K11+P11+Q11+W11+X11 | AB11: =G11-AA11-L11-R11-Y11+U11-I11 | AC11: =AC10+AB11 | AD11: =M11+S11+Z11 | AE11: =J11+K11+O11+P11+V11+W11 | AF11: =AF10+AE11 | AG11: =IF(AD11<0.01,1,0)
A12: =DATE(YEAR(A11),MONTH(A11)+1,1) | B12: =IF(A12=Supuestos!$B$5,Supuestos!$B$7,Supuestos!$B$6) | C12: =IF(A12=Supuestos!$B$16,Supuestos!$B$15,0) | D12: =IF(A12=Supuestos!$B$5,Supuestos!$B$8,Supuestos!$B$43) | E12: =IF(AND(A12>Supuestos!$B$5,A12<=Supuestos!$B$12),Supuestos!$B$11,0) | F12: =IF(A12>=Supuestos!$B$14,Supuestos!$B$13,0) | G12: =B12+C12-D12-E12-F12 | H12: =M11 | I12: =MIN(U12,H12) | J12: =(H12-I12)*Supuestos!$B$46 | K12: =IF(H12-I12>0.01,MIN(Supuestos!$B$21,(H12-I12)*Supuestos!$B$20),0) | L12: =MIN(MAX(G12-AA12,0),H12-I12) | M12: =H12-I12-L12 | N12: =S11 | O12: =IF(A12=Supuestos!$B$5,0,N12*Supuestos!$B$47) | P12: =IF(AND(A12>Supuestos!$B$5,N12>0.01),Supuestos!$B$26,0) | Q12: =IF(A12=Supuestos!$B$5,0,MIN(Supuestos!$B$25,N12+O12)) | R12: =$B$4*MIN(MAX(G12-AA12-L12,0),N12+O12-Q12) | S12: =N12+O12-Q12-R12 | T12: =Z11 | U12: =IF(A12=Supuestos!$B$5,$B$3*Supuestos!$B$28,0) | V12: =T12*Supuestos!$B$48 | W12: =IF(T12>0.01,Supuestos!$B$58,0) | X12: =MIN(Supuestos!$B$57,T12+V12) | Y12: =$B$5*MIN(MAX(G12-AA12-L12-R12,0),T12+V12-X12) | Z12: =T12+U12+V12-X12-Y12 | AA12: =J12+K12+P12+Q12+W12+X12 | AB12: =G12-AA12-L12-R12-Y12+U12-I12 | AC12: =AC11+AB12 | AD12: =M12+S12+Z12 | AE12: =J12+K12+O12+P12+V12+W12 | AF12: =AF11+AE12 | AG12: =IF(AD12<0.01,1,0)
A13: =DATE(YEAR(A12),MONTH(A12)+1,1) | B13: =IF(A13=Supuestos!$B$5,Supuestos!$B$7,Supuestos!$B$6) | C13: =IF(A13=Supuestos!$B$16,Supuestos!$B$15,0) | D13: =IF(A13=Supuestos!$B$5,Supuestos!$B$8,Supuestos!$B$43) | E13: =IF(AND(A13>Supuestos!$B$5,A13<=Supuestos!$B$12),Supuestos!$B$11,0) | F13: =IF(A13>=Supuestos!$B$14,Supuestos!$B$13,0) | G13: =B13+C13-D13-E13-F13 | H13: =M12 | I13: =MIN(U13,H13) | J13: =(H13-I13)*Supuestos!$B$46 | K13: =IF(H13-I13>0.01,MIN(Supuestos!$B$21,(H13-I13)*Supuestos!$B$20),0) | L13: =MIN(MAX(G13-AA13,0),H13-I13) | M13: =H13-I13-L13 | N13: =S12 | O13: =IF(A13=Supuestos!$B$5,0,N13*Supuestos!$B$47) | P13: =IF(AND(A13>Supuestos!$B$5,N13>0.01),Supuestos!$B$26,0) | Q13: =IF(A13=Supuestos!$B$5,0,MIN(Supuestos!$B$25,N13+O13)) | R13: =$B$4*MIN(MAX(G13-AA13-L13,0),N13+O13-Q13) | S13: =N13+O13-Q13-R13 | T13: =Z12 | U13: =IF(A13=Supuestos!$B$5,$B$3*Supuestos!$B$28,0) | V13: =T13*Supuestos!$B$48 | W13: =IF(T13>0.01,Supuestos!$B$58,0) | X13: =MIN(Supuestos!$B$57,T13+V13) | Y13: =$B$5*MIN(MAX(G13-AA13-L13-R13,0),T13+V13-X13) | Z13: =T13+U13+V13-X13-Y13 | AA13: =J13+K13+P13+Q13+W13+X13 | AB13: =G13-AA13-L13-R13-Y13+U13-I13 | AC13: =AC12+AB13 | AD13: =M13+S13+Z13 | AE13: =J13+K13+O13+P13+V13+W13 | AF13: =AF12+AE13 | AG13: =IF(AD13<0.01,1,0)
A14: =DATE(YEAR(A13),MONTH(A13)+1,1) | B14: =IF(A14=Supuestos!$B$5,Supuestos!$B$7,Supuestos!$B$6) | C14: =IF(A14=Supuestos!$B$16,Supuestos!$B$15,0) | D14: =IF(A14=Supuestos!$B$5,Supuestos!$B$8,Supuestos!$B$43) | E14: =IF(AND(A14>Supuestos!$B$5,A14<=Supuestos!$B$12),Supuestos!$B$11,0) | F14: =IF(A14>=Supuestos!$B$14,Supuestos!$B$13,0) | G14: =B14+C14-D14-E14-F14 | H14: =M13 | I14: =MIN(U14,H14) | J14: =(H14-I14)*Supuestos!$B$46 | K14: =IF(H14-I14>0.01,MIN(Supuestos!$B$21,(H14-I14)*Supuestos!$B$20),0) | L14: =MIN(MAX(G14-AA14,0),H14-I14) | M14: =H14-I14-L14 | N14: =S13 | O14: =IF(A14=Supuestos!$B$5,0,N14*Supuestos!$B$47) | P14: =IF(AND(A14>Supuestos!$B$5,N14>0.01),Supuestos!$B$26,0) | Q14: =IF(A14=Supuestos!$B$5,0,MIN(Supuestos!$B$25,N14+O14)) | R14: =$B$4*MIN(MAX(G14-AA14-L14,0),N14+O14-Q14) | S14: =N14+O14-Q14-R14 | T14: =Z13 | U14: =IF(A14=Supuestos!$B$5,$B$3*Supuestos!$B$28,0) | V14: =T14*Supuestos!$B$48 | W14: =IF(T14>0.01,Supuestos!$B$58,0) | X14: =MIN(Supuestos!$B$57,T14+V14) | Y14: =$B$5*MIN(MAX(G14-AA14-L14-R14,0),T14+V14-X14) | Z14: =T14+U14+V14-X14-Y14 | AA14: =J14+K14+P14+Q14+W14+X14 | AB14: =G14-AA14-L14-R14-Y14+U14-I14 | AC14: =AC13+AB14 | AD14: =M14+S14+Z14 | AE14: =J14+K14+O14+P14+V14+W14 | AF14: =AF13+AE14 | AG14: =IF(AD14<0.01,1,0)
A15: =DATE(YEAR(A14),MONTH(A14)+1,1) | B15: =IF(A15=Supuestos!$B$5,Supuestos!$B$7,Supuestos!$B$6) | C15: =IF(A15=Supuestos!$B$16,Supuestos!$B$15,0) | D15: =IF(A15=Supuestos!$B$5,Supuestos!$B$8,Supuestos!$B$43) | E15: =IF(AND(A15>Supuestos!$B$5,A15<=Supuestos!$B$12),Supuestos!$B$11,0) | F15: =IF(A15>=Supuestos!$B$14,Supuestos!$B$13,0) | G15: =B15+C15-D15-E15-F15 | H15: =M14 | I15: =MIN(U15,H15) | J15: =(H15-I15)*Supuestos!$B$46 | K15: =IF(H15-I15>0.01,MIN(Supuestos!$B$21,(H15-I15)*Supuestos!$B$20),0) | L15: =MIN(MAX(G15-AA15,0),H15-I15) | M15: =H15-I15-L15 | N15: =S14 | O15: =IF(A15=Supuestos!$B$5,0,N15*Supuestos!$B$47) | P15: =IF(AND(A15>Supuestos!$B$5,N15>0.01),Supuestos!$B$26,0) | Q15: =IF(A15=Supuestos!$B$5,0,MIN(Supuestos!$B$25,N15+O15)) | R15: =$B$4*MIN(MAX(G15-AA15-L15,0),N15+O15-Q15) | S15: =N15+O15-Q15-R15 | T15: =Z14 | U15: =IF(A15=Supuestos!$B$5,$B$3*Supuestos!$B$28,0) | V15: =T15*Supuestos!$B$48 | W15: =IF(T15>0.01,Supuestos!$B$58,0) | X15: =MIN(Supuestos!$B$57,T15+V15) | Y15: =$B$5*MIN(MAX(G15-AA15-L15-R15,0),T15+V15-X15) | Z15: =T15+U15+V15-X15-Y15 | AA15: =J15+K15+P15+Q15+W15+X15 | AB15: =G15-AA15-L15-R15-Y15+U15-I15 | AC15: =AC14+AB15 | AD15: =M15+S15+Z15 | AE15: =J15+K15+O15+P15+V15+W15 | AF15: =AF14+AE15 | AG15: =IF(AD15<0.01,1,0)
A16: =DATE(YEAR(A15),MONTH(A15)+1,1) | B16: =IF(A16=Supuestos!$B$5,Supuestos!$B$7,Supuestos!$B$6) | C16: =IF(A16=Supuestos!$B$16,Supuestos!$B$15,0) | D16: =IF(A16=Supuestos!$B$5,Supuestos!$B$8,Supuestos!$B$43) | E16: =IF(AND(A16>Supuestos!$B$5,A16<=Supuestos!$B$12),Supuestos!$B$11,0) | F16: =IF(A16>=Supuestos!$B$14,Supuestos!$B$13,0) | G16: =B16+C16-D16-E16-F16 | H16: =M15 | I16: =MIN(U16,H16) | J16: =(H16-I16)*Supuestos!$B$46 | K16: =IF(H16-I16>0.01,MIN(Supuestos!$B$21,(H16-I16)*Supuestos!$B$20),0) | L16: =MIN(MAX(G16-AA16,0),H16-I16) | M16: =H16-I16-L16 | N16: =S15 | O16: =IF(A16=Supuestos!$B$5,0,N16*Supuestos!$B$47) | P16: =IF(AND(A16>Supuestos!$B$5,N16>0.01),Supuestos!$B$26,0) | Q16: =IF(A16=Supuestos!$B$5,0,MIN(Supuestos!$B$25,N16+O16)) | R16: =$B$4*MIN(MAX(G16-AA16-L16,0),N16+O16-Q16) | S16: =N16+O16-Q16-R16 | T16: =Z15 | U16: =IF(A16=Supuestos!$B$5,$B$3*Supuestos!$B$28,0) | V16: =T16*Supuestos!$B$48 | W16: =IF(T16>0.01,Supuestos!$B$58,0) | X16: =MIN(Supuestos!$B$57,T16+V16) | Y16: =$B$5*MIN(MAX(G16-AA16-L16-R16,0),T16+V16-X16) | Z16: =T16+U16+V16-X16-Y16 | AA16: =J16+K16+P16+Q16+W16+X16 | AB16: =G16-AA16-L16-R16-Y16+U16-I16 | AC16: =AC15+AB16 | AD16: =M16+S16+Z16 | AE16: =J16+K16+O16+P16+V16+W16 | AF16: =AF15+AE16 | AG16: =IF(AD16<0.01,1,0)
A17: =DATE(YEAR(A16),MONTH(A16)+1,1) | B17: =IF(A17=Supuestos!$B$5,Supuestos!$B$7,Supuestos!$B$6) | C17: =IF(A17=Supuestos!$B$16,Supuestos!$B$15,0) | D17: =IF(A17=Supuestos!$B$5,Supuestos!$B$8,Supuestos!$B$43) | E17: =IF(AND(A17>Supuestos!$B$5,A17<=Supuestos!$B$12),Supuestos!$B$11,0) | F17: =IF(A17>=Supuestos!$B$14,Supuestos!$B$13,0) | G17: =B17+C17-D17-E17-F17 | H17: =M16 | I17: =MIN(U17,H17) | J17: =(H17-I17)*Supuestos!$B$46 | K17: =IF(H17-I17>0.01,MIN(Supuestos!$B$21,(H17-I17)*Supuestos!$B$20),0) | L17: =MIN(MAX(G17-AA17,0),H17-I17) | M17: =H17-I17-L17 | N17: =S16 | O17: =IF(A17=Supuestos!$B$5,0,N17*Supuestos!$B$47) | P17: =IF(AND(A17>Supuestos!$B$5,N17>0.01),Supuestos!$B$26,0) | Q17: =IF(A17=Supuestos!$B$5,0,MIN(Supuestos!$B$25,N17+O17)) | R17: =$B$4*MIN(MAX(G17-AA17-L17,0),N17+O17-Q17) | S17: =N17+O17-Q17-R17 | T17: =Z16 | U17: =IF(A17=Supuestos!$B$5,$B$3*Supuestos!$B$28,0) | V17: =T17*Supuestos!$B$48 | W17: =IF(T17>0.01,Supuestos!$B$58,0) | X17: =MIN(Supuestos!$B$57,T17+V17) | Y17: =$B$5*MIN(MAX(G17-AA17-L17-R17,0),T17+V17-X17) | Z17: =T17+U17+V17-X17-Y17 | AA17: =J17+K17+P17+Q17+W17+X17 | AB17: =G17-AA17-L17-R17-Y17+U17-I17 | AC17: =AC16+AB17 | AD17: =M17+S17+Z17 | AE17: =J17+K17+O17+P17+V17+W17 | AF17: =AF16+AE17 | AG17: =IF(AD17<0.01,1,0)
A18: =DATE(YEAR(A17),MONTH(A17)+1,1) | B18: =IF(A18=Supuestos!$B$5,Supuestos!$B$7,Supuestos!$B$6) | C18: =IF(A18=Supuestos!$B$16,Supuestos!$B$15,0) | D18: =IF(A18=Supuestos!$B$5,Supuestos!$B$8,Supuestos!$B$43) | E18: =IF(AND(A18>Supuestos!$B$5,A18<=Supuestos!$B$12),Supuestos!$B$11,0) | F18: =IF(A18>=Supuestos!$B$14,Supuestos!$B$13,0) | G18: =B18+C18-D18-E18-F18 | H18: =M17 | I18: =MIN(U18,H18) | J18: =(H18-I18)*Supuestos!$B$46 | K18: =IF(H18-I18>0.01,MIN(Supuestos!$B$21,(H18-I18)*Supuestos!$B$20),0) | L18: =MIN(MAX(G18-AA18,0),H18-I18) | M18: =H18-I18-L18 | N18: =S17 | O18: =IF(A18=Supuestos!$B$5,0,N18*Supuestos!$B$47) | P18: =IF(AND(A18>Supuestos!$B$5,N18>0.01),Supuestos!$B$26,0) | Q18: =IF(A18=Supuestos!$B$5,0,MIN(Supuestos!$B$25,N18+O18)) | R18: =$B$4*MIN(MAX(G18-AA18-L18,0),N18+O18-Q18) | S18: =N18+O18-Q18-R18 | T18: =Z17 | U18: =IF(A18=Supuestos!$B$5,$B$3*Supuestos!$B$28,0) | V18: =T18*Supuestos!$B$48 | W18: =IF(T18>0.01,Supuestos!$B$58,0) | X18: =MIN(Supuestos!$B$57,T18+V18) | Y18: =$B$5*MIN(MAX(G18-AA18-L18-R18,0),T18+V18-X18) | Z18: =T18+U18+V18-X18-Y18 | AA18: =J18+K18+P18+Q18+W18+X18 | AB18: =G18-AA18-L18-R18-Y18+U18-I18 | AC18: =AC17+AB18 | AD18: =M18+S18+Z18 | AE18: =J18+K18+O18+P18+V18+W18 | AF18: =AF17+AE18 | AG18: =IF(AD18<0.01,1,0)
A19: =DATE(YEAR(A18),MONTH(A18)+1,1) | B19: =IF(A19=Supuestos!$B$5,Supuestos!$B$7,Supuestos!$B$6) | C19: =IF(A19=Supuestos!$B$16,Supuestos!$B$15,0) | D19: =IF(A19=Supuestos!$B$5,Supuestos!$B$8,Supuestos!$B$43) | E19: =IF(AND(A19>Supuestos!$B$5,A19<=Supuestos!$B$12),Supuestos!$B$11,0) | F19: =IF(A19>=Supuestos!$B$14,Supuestos!$B$13,0) | G19: =B19+C19-D19-E19-F19 | H19: =M18 | I19: =MIN(U19,H19) | J19: =(H19-I19)*Supuestos!$B$46 | K19: =IF(H19-I19>0.01,MIN(Supuestos!$B$21,(H19-I19)*Supuestos!$B$20),0) | L19: =MIN(MAX(G19-AA19,0),H19-I19) | M19: =H19-I19-L19 | N19: =S18 | O19: =IF(A19=Supuestos!$B$5,0,N19*Supuestos!$B$47) | P19: =IF(AND(A19>Supuestos!$B$5,N19>0.01),Supuestos!$B$26,0) | Q19: =IF(A19=Supuestos!$B$5,0,MIN(Supuestos!$B$25,N19+O19)) | R19: =$B$4*MIN(MAX(G19-AA19-L19,0),N19+O19-Q19) | S19: =N19+O19-Q19-R19 | T19: =Z18 | U19: =IF(A19=Supuestos!$B$5,$B$3*Supuestos!$B$28,0) | V19: =T19*Supuestos!$B$48 | W19: =IF(T19>0.01,Supuestos!$B$58,0) | X19: =MIN(Supuestos!$B$57,T19+V19) | Y19: =$B$5*MIN(MAX(G19-AA19-L19-R19,0),T19+V19-X19) | Z19: =T19+U19+V19-X19-Y19 | AA19: =J19+K19+P19+Q19+W19+X19 | AB19: =G19-AA19-L19-R19-Y19+U19-I19 | AC19: =AC18+AB19 | AD19: =M19+S19+Z19 | AE19: =J19+K19+O19+P19+V19+W19 | AF19: =AF18+AE19 | AG19: =IF(AD19<0.01,1,0)
A20: =DATE(YEAR(A19),MONTH(A19)+1,1) | B20: =IF(A20=Supuestos!$B$5,Supuestos!$B$7,Supuestos!$B$6) | C20: =IF(A20=Supuestos!$B$16,Supuestos!$B$15,0) | D20: =IF(A20=Supuestos!$B$5,Supuestos!$B$8,Supuestos!$B$43) | E20: =IF(AND(A20>Supuestos!$B$5,A20<=Supuestos!$B$12),Supuestos!$B$11,0) | F20: =IF(A20>=Supuestos!$B$14,Supuestos!$B$13,0) | G20: =B20+C20-D20-E20-F20 | H20: =M19 | I20: =MIN(U20,H20) | J20: =(H20-I20)*Supuestos!$B$46 | K20: =IF(H20-I20>0.01,MIN(Supuestos!$B$21,(H20-I20)*Supuestos!$B$20),0) | L20: =MIN(MAX(G20-AA20,0),H20-I20) | M20: =H20-I20-L20 | N20: =S19 | O20: =IF(A20=Supuestos!$B$5,0,N20*Supuestos!$B$47) | P20: =IF(AND(A20>Supuestos!$B$5,N20>0.01),Supuestos!$B$26,0) | Q20: =IF(A20=Supuestos!$B$5,0,MIN(Supuestos!$B$25,N20+O20)) | R20: =$B$4*MIN(MAX(G20-AA20-L20,0),N20+O20-Q20) | S20: =N20+O20-Q20-R20 | T20: =Z19 | U20: =IF(A20=Supuestos!$B$5,$B$3*Supuestos!$B$28,0) | V20: =T20*Supuestos!$B$48 | W20: =IF(T20>0.01,Supuestos!$B$58,0) | X20: =MIN(Supuestos!$B$57,T20+V20) | Y20: =$B$5*MIN(MAX(G20-AA20-L20-R20,0),T20+V20-X20) | Z20: =T20+U20+V20-X20-Y20 | AA20: =J20+K20+P20+Q20+W20+X20 | AB20: =G20-AA20-L20-R20-Y20+U20-I20 | AC20: =AC19+AB20 | AD20: =M20+S20+Z20 | AE20: =J20+K20+O20+P20+V20+W20 | AF20: =AF19+AE20 | AG20: =IF(AD20<0.01,1,0)
... A34: =DATE(YEAR(A33),MONTH(A33)+1,1) | B34: =IF(A34=Supuestos!$B$5,Supuestos!$B$7,Supuestos!$B$6) | C34: =IF(A34=Supuestos!$B$16,Supuestos!$B$15,0) | D34: =IF(A34=Supuestos!$B$5,Supuestos!$B$8,Supuestos!$B$43) | E34: =IF(AND(A34>Supuestos!$B$5,A34<=Supuestos!$B$12),Supuestos!$B$11,0) | F34: =IF(A34>=Supuestos!$B$14,Supuestos!$B$13,0) | G34: =B34+C34-D34-E34-F34 | H34: =M33 | I34: =MIN(U34,H34) | J34: =(H34-I34)*Supuestos!$B$46 | K34: =IF(H34-I34>0.01,MIN(Supuestos!$B$21,(H34-I34)*Supuestos!$B$20),0) | L34: =MIN(MAX(G34-AA34,0),H34-I34) | M34: =H34-I34-L34 | N34: =S33 | O34: =IF(A34=Supuestos!$B$5,0,N34*Supuestos!$B$47) | P34: =IF(AND(A34>Supuestos!$B$5,N34>0.01),Supuestos!$B$26,0) | Q34: =IF(A34=Supuestos!$B$5,0,MIN(Supuestos!$B$25,N34+O34)) | R34: =$B$4*MIN(MAX(G34-AA34-L34,0),N34+O34-Q34) | S34: =N34+O34-Q34-R34 | T34: =Z33 | U34: =IF(A34=Supuestos!$B$5,$B$3*Supuestos!$B$28,0) | V34: =T34*Supuestos!$B$48 | W34: =IF(T34>0.01,Supuestos!$B$58,0) | X34: =MIN(Supuestos!$B$57,T34+V34) | Y34: =$B$5*MIN(MAX(G34-AA34-L34-R34,0),T34+V34-X34) | Z34: =T34+U34+V34-X34-Y34 | AA34: =J34+K34+P34+Q34+W34+X34 | AB34: =G34-AA34-L34-R34-Y34+U34-I34 | AC34: =AC33+AB34 | AD34: =M34+S34+Z34 | AE34: =J34+K34+O34+P34+V34+W34 | AF34: =AF33+AE34 | AG34: =IF(AD34<0.01,1,0)

Sheet B Sin préstamo
A1: B Sin préstamo
A2: No pide préstamo. Todo el sobrante va a la tarjeta, luego al EC actual.
A3: Usa préstamo nuevo (1/0) | B3: 0 | D3: Ahorro negativo = déficit: el plan no alcanza ese mes.
A4: Prepagar EC actual (1/0) | B4: 1
A5: Prepagar préstamo nuevo (1/0) | B5: 0
A7: Mes | B7: Ingreso | C7: Devolución impuestos | D7: Gastos de vida | E7: Pensión | F7: Alquiler | G7: Disponible | H7: Tarjeta saldo inicial | I7: Pagado con préstamo | J7: Interés tarjeta | K7: Seguro tarjeta | L7: Pago extra tarjeta | M7: Tarjeta saldo final | N7: EC actual saldo inicial | O7: Interés EC | P7: Seguro EC | Q7: Cuota EC | R7: Prepago EC | S7: EC saldo final | T7: Préstamo nuevo saldo inicial | U7: Desembolso | V7: Interés préstamo | W7: Seguro préstamo | X7: Cuota préstamo | Y7: Prepago préstamo | Z7: Préstamo saldo final | AA7: Pagos obligatorios | AB7: Ahorro del mes | AC7: Ahorro acumulado | AD7: Deuda total | AE7: Costo financiero del mes | AF7: Costo financiero acumulado | AG7: Libre de deuda
A8: =Supuestos!$B$5 | B8: =IF(A8=Supuestos!$B$5,Supuestos!$B$7,Supuestos!$B$6) | C8: =IF(A8=Supuestos!$B$16,Supuestos!$B$15,0) | D8: =IF(A8=Supuestos!$B$5,Supuestos!$B$8,Supuestos!$B$43) | E8: =IF(AND(A8>Supuestos!$B$5,A8<=Supuestos!$B$12),Supuestos!$B$11,0) | F8: =IF(A8>=Supuestos!$B$14,Supuestos!$B$13,0) | G8: =B8+C8-D8-E8-F8 | H8: =Supuestos!$B$18 | I8: =MIN(U8,H8) | J8: =(H8-I8)*Supuestos!$B$46 | K8: =IF(H8-I8>0.01,MIN(Supuestos!$B$21,(H8-I8)*Supuestos!$B$20),0) | L8: =MIN(MAX(G8-AA8,0),H8-I8) | M8: =H8-I8-L8 | N8: =Supuestos!$B$23 | O8: =IF(A8=Supuestos!$B$5,0,N8*Supuestos!$B$47) | P8: =IF(AND(A8>Supuestos!$B$5,N8>0.01),Supuestos!$B$26,0) | Q8: =IF(A8=Supuestos!$B$5,0,MIN(Supuestos!$B$25,N8+O8)) | R8: =$B$4*MIN(MAX(G8-AA8-L8,0),N8+O8-Q8) | S8: =N8+O8-Q8-R8 | T8: =0 | U8: =IF(A8=Supuestos!$B$5,$B$3*Supuestos!$B$28,0) | V8: =T8*Supuestos!$B$48 | W8: =IF(T8>0.01,Supuestos!$B$58,0) | X8: =MIN(Supuestos!$B$57,T8+V8) | Y8: =$B$5*MIN(MAX(G8-AA8-L8-R8,0),T8+V8-X8) | Z8: =T8+U8+V8-X8-Y8 | AA8: =J8+K8+P8+Q8+W8+X8 | AB8: =G8-AA8-L8-R8-Y8+U8-I8 | AC8: =AB8 | AD8: =M8+S8+Z8 | AE8: =J8+K8+O8+P8+V8+W8 | AF8: =AE8 | AG8: =IF(AD8<0.01,1,0)
A9: =DATE(YEAR(A8),MONTH(A8)+1,1) | B9: =IF(A9=Supuestos!$B$5,Supuestos!$B$7,Supuestos!$B$6) | C9: =IF(A9=Supuestos!$B$16,Supuestos!$B$15,0) | D9: =IF(A9=Supuestos!$B$5,Supuestos!$B$8,Supuestos!$B$43) | E9: =IF(AND(A9>Supuestos!$B$5,A9<=Supuestos!$B$12),Supuestos!$B$11,0) | F9: =IF(A9>=Supuestos!$B$14,Supuestos!$B$13,0) | G9: =B9+C9-D9-E9-F9 | H9: =M8 | I9: =MIN(U9,H9) | J9: =(H9-I9)*Supuestos!$B$46 | K9: =IF(H9-I9>0.01,MIN(Supuestos!$B$21,(H9-I9)*Supuestos!$B$20),0) | L9: =MIN(MAX(G9-AA9,0),H9-I9) | M9: =H9-I9-L9 | N9: =S8 | O9: =IF(A9=Supuestos!$B$5,0,N9*Supuestos!$B$47) | P9: =IF(AND(A9>Supuestos!$B$5,N9>0.01),Supuestos!$B$26,0) | Q9: =IF(A9=Supuestos!$B$5,0,MIN(Supuestos!$B$25,N9+O9)) | R9: =$B$4*MIN(MAX(G9-AA9-L9,0),N9+O9-Q9) | S9: =N9+O9-Q9-R9 | T9: =Z8 | U9: =IF(A9=Supuestos!$B$5,$B$3*Supuestos!$B$28,0) | V9: =T9*Supuestos!$B$48 | W9: =IF(T9>0.01,Supuestos!$B$58,0) | X9: =MIN(Supuestos!$B$57,T9+V9) | Y9: =$B$5*MIN(MAX(G9-AA9-L9-R9,0),T9+V9-X9) | Z9: =T9+U9+V9-X9-Y9 | AA9: =J9+K9+P9+Q9+W9+X9 | AB9: =G9-AA9-L9-R9-Y9+U9-I9 | AC9: =AC8+AB9 | AD9: =M9+S9+Z9 | AE9: =J9+K9+O9+P9+V9+W9 | AF9: =AF8+AE9 | AG9: =IF(AD9<0.01,1,0)
A10: =DATE(YEAR(A9),MONTH(A9)+1,1) | B10: =IF(A10=Supuestos!$B$5,Supuestos!$B$7,Supuestos!$B$6) | C10: =IF(A10=Supuestos!$B$16,Supuestos!$B$15,0) | D10: =IF(A10=Supuestos!$B$5,Supuestos!$B$8,Supuestos!$B$43) | E10: =IF(AND(A10>Supuestos!$B$5,A10<=Supuestos!$B$12),Supuestos!$B$11,0) | F10: =IF(A10>=Supuestos!$B$14,Supuestos!$B$13,0) | G10: =B10+C10-D10-E10-F10 | H10: =M9 | I10: =MIN(U10,H10) | J10: =(H10-I10)*Supuestos!$B$46 | K10: =IF(H10-I10>0.01,MIN(Supuestos!$B$21,(H10-I10)*Supuestos!$B$20),0) | L10: =MIN(MAX(G10-AA10,0),H10-I10) | M10: =H10-I10-L10 | N10: =S9 | O10: =IF(A10=Supuestos!$B$5,0,N10*Supuestos!$B$47) | P10: =IF(AND(A10>Supuestos!$B$5,N10>0.01),Supuestos!$B$26,0) | Q10: =IF(A10=Supuestos!$B$5,0,MIN(Supuestos!$B$25,N10+O10)) | R10: =$B$4*MIN(MAX(G10-AA10-L10,0),N10+O10-Q10) | S10: =N10+O10-Q10-R10 | T10: =Z9 | U10: =IF(A10=Supuestos!$B$5,$B$3*Supuestos!$B$28,0) | V10: =T10*Supuestos!$B$48 | W10: =IF(T10>0.01,Supuestos!$B$58,0) | X10: =MIN(Supuestos!$B$57,T10+V10) | Y10: =$B$5*MIN(MAX(G10-AA10-L10-R10,0),T10+V10-X10) | Z10: =T10+U10+V10-X10-Y10 | AA10: =J10+K10+P10+Q10+W10+X10 | AB10: =G10-AA10-L10-R10-Y10+U10-I10 | AC10: =AC9+AB10 | AD10: =M10+S10+Z10 | AE10: =J10+K10+O10+P10+V10+W10 | AF10: =AF9+AE10 | AG10: =IF(AD10<0.01,1,0)
A11: =DATE(YEAR(A10),MONTH(A10)+1,1) | B11: =IF(A11=Supuestos!$B$5,Supuestos!$B$7,Supuestos!$B$6) | C11: =IF(A11=Supuestos!$B$16,Supuestos!$B$15,0) | D11: =IF(A11=Supuestos!$B$5,Supuestos!$B$8,Supuestos!$B$43) | E11: =IF(AND(A11>Supuestos!$B$5,A11<=Supuestos!$B$12),Supuestos!$B$11,0) | F11: =IF(A11>=Supuestos!$B$14,Supuestos!$B$13,0) | G11: =B11+C11-D11-E11-F11 | H11: =M10 | I11: =MIN(U11,H11) | J11: =(H11-I11)*Supuestos!$B$46 | K11: =IF(H11-I11>0.01,MIN(Supuestos!$B$21,(H11-I11)*Supuestos!$B$20),0) | L11: =MIN(MAX(G11-AA11,0),H11-I11) | M11: =H11-I11-L11 | N11: =S10 | O11: =IF(A11=Supuestos!$B$5,0,N11*Supuestos!$B$47) | P11: =IF(AND(A11>Supuestos!$B$5,N11>0.01),Supuestos!$B$26,0) | Q11: =IF(A11=Supuestos!$B$5,0,MIN(Supuestos!$B$25,N11+O11)) | R11: =$B$4*MIN(MAX(G11-AA11-L11,0),N11+O11-Q11) | S11: =N11+O11-Q11-R11 | T11: =Z10 | U11: =IF(A11=Supuestos!$B$5,$B$3*Supuestos!$B$28,0) | V11: =T11*Supuestos!$B$48 | W11: =IF(T11>0.01,Supuestos!$B$58,0) | X11: =MIN(Supuestos!$B$57,T11+V11) | Y11: =$B$5*MIN(MAX(G11-AA11-L11-R11,0),T11+V11-X11) | Z11: =T11+U11+V11-X11-Y11 | AA11: =J11+K11+P11+Q11+W11+X11 | AB11: =G11-AA11-L11-R11-Y11+U11-I11 | AC11: =AC10+AB11 | AD11: =M11+S11+Z11 | AE11: =J11+K11+O11+P11+V11+W11 | AF11: =AF10+AE11 | AG11: =IF(AD11<0.01,1,0)
A12: =DATE(YEAR(A11),MONTH(A11)+1,1) | B12: =IF(A12=Supuestos!$B$5,Supuestos!$B$7,Supuestos!$B$6) | C12: =IF(A12=Supuestos!$B$16,Supuestos!$B$15,0) | D12: =IF(A12=Supuestos!$B$5,Supuestos!$B$8,Supuestos!$B$43) | E12: =IF(AND(A12>Supuestos!$B$5,A12<=Supuestos!$B$12),Supuestos!$B$11,0) | F12: =IF(A12>=Supuestos!$B$14,Supuestos!$B$13,0) | G12: =B12+C12-D12-E12-F12 | H12: =M11 | I12: =MIN(U12,H12) | J12: =(H12-I12)*Supuestos!$B$46 | K12: =IF(H12-I12>0.01,MIN(Supuestos!$B$21,(H12-I12)*Supuestos!$B$20),0) | L12: =MIN(MAX(G12-AA12,0),H12-I12) | M12: =H12-I12-L12 | N12: =S11 | O12: =IF(A12=Supuestos!$B$5,0,N12*Supuestos!$B$47) | P12: =IF(AND(A12>Supuestos!$B$5,N12>0.01),Supuestos!$B$26,0) | Q12: =IF(A12=Supuestos!$B$5,0,MIN(Supuestos!$B$25,N12+O12)) | R12: =$B$4*MIN(MAX(G12-AA12-L12,0),N12+O12-Q12) | S12: =N12+O12-Q12-R12 | T12: =Z11 | U12: =IF(A12=Supuestos!$B$5,$B$3*Supuestos!$B$28,0) | V12: =T12*Supuestos!$B$48 | W12: =IF(T12>0.01,Supuestos!$B$58,0) | X12: =MIN(Supuestos!$B$57,T12+V12) | Y12: =$B$5*MIN(MAX(G12-AA12-L12-R12,0),T12+V12-X12) | Z12: =T12+U12+V12-X12-Y12 | AA12: =J12+K12+P12+Q12+W12+X12 | AB12: =G12-AA12-L12-R12-Y12+U12-I12 | AC12: =AC11+AB12 | AD12: =M12+S12+Z12 | AE12: =J12+K12+O12+P12+V12+W12 | AF12: =AF11+AE12 | AG12: =IF(AD12<0.01,1,0)
A13: =DATE(YEAR(A12),MONTH(A12)+1,1) | B13: =IF(A13=Supuestos!$B$5,Supuestos!$B$7,Supuestos!$B$6) | C13: =IF(A13=Supuestos!$B$16,Supuestos!$B$15,0) | D13: =IF(A13=Supuestos!$B$5,Supuestos!$B$8,Supuestos!$B$43) | E13: =IF(AND(A13>Supuestos!$B$5,A13<=Supuestos!$B$12),Supuestos!$B$11,0) | F13: =IF(A13>=Supuestos!$B$14,Supuestos!$B$13,0) | G13: =B13+C13-D13-E13-F13 | H13: =M12 | I13: =MIN(U13,H13) | J13: =(H13-I13)*Supuestos!$B$46 | K13: =IF(H13-I13>0.01,MIN(Supuestos!$B$21,(H13-I13)*Supuestos!$B$20),0) | L13: =MIN(MAX(G13-AA13,0),H13-I13) | M13: =H13-I13-L13 | N13: =S12 | O13: =IF(A13=Supuestos!$B$5,0,N13*Supuestos!$B$47) | P13: =IF(AND(A13>Supuestos!$B$5,N13>0.01),Supuestos!$B$26,0) | Q13: =IF(A13=Supuestos!$B$5,0,MIN(Supuestos!$B$25,N13+O13)) | R13: =$B$4*MIN(MAX(G13-AA13-L13,0),N13+O13-Q13) | S13: =N13+O13-Q13-R13 | T13: =Z12 | U13: =IF(A13=Supuestos!$B$5,$B$3*Supuestos!$B$28,0) | V13: =T13*Supuestos!$B$48 | W13: =IF(T13>0.01,Supuestos!$B$58,0) | X13: =MIN(Supuestos!$B$57,T13+V13) | Y13: =$B$5*MIN(MAX(G13-AA13-L13-R13,0),T13+V13-X13) | Z13: =T13+U13+V13-X13-Y13 | AA13: =J13+K13+P13+Q13+W13+X13 | AB13: =G13-AA13-L13-R13-Y13+U13-I13 | AC13: =AC12+AB13 | AD13: =M13+S13+Z13 | AE13: =J13+K13+O13+P13+V13+W13 | AF13: =AF12+AE13 | AG13: =IF(AD13<0.01,1,0)
A14: =DATE(YEAR(A13),MONTH(A13)+1,1) | B14: =IF(A14=Supuestos!$B$5,Supuestos!$B$7,Supuestos!$B$6) | C14: =IF(A14=Supuestos!$B$16,Supuestos!$B$15,0) | D14: =IF(A14=Supuestos!$B$5,Supuestos!$B$8,Supuestos!$B$43) | E14: =IF(AND(A14>Supuestos!$B$5,A14<=Supuestos!$B$12),Supuestos!$B$11,0) | F14: =IF(A14>=Supuestos!$B$14,Supuestos!$B$13,0) | G14: =B14+C14-D14-E14-F14 | H14: =M13 | I14: =MIN(U14,H14) | J14: =(H14-I14)*Supuestos!$B$46 | K14: =IF(H14-I14>0.01,MIN(Supuestos!$B$21,(H14-I14)*Supuestos!$B$20),0) | L14: =MIN(MAX(G14-AA14,0),H14-I14) | M14: =H14-I14-L14 | N14: =S13 | O14: =IF(A14=Supuestos!$B$5,0,N14*Supuestos!$B$47) | P14: =IF(AND(A14>Supuestos!$B$5,N14>0.01),Supuestos!$B$26,0) | Q14: =IF(A14=Supuestos!$B$5,0,MIN(Supuestos!$B$25,N14+O14)) | R14: =$B$4*MIN(MAX(G14-AA14-L14,0),N14+O14-Q14) | S14: =N14+O14-Q14-R14 | T14: =Z13 | U14: =IF(A14=Supuestos!$B$5,$B$3*Supuestos!$B$28,0) | V14: =T14*Supuestos!$B$48 | W14: =IF(T14>0.01,Supuestos!$B$58,0) | X14: =MIN(Supuestos!$B$57,T14+V14) | Y14: =$B$5*MIN(MAX(G14-AA14-L14-R14,0),T14+V14-X14) | Z14: =T14+U14+V14-X14-Y14 | AA14: =J14+K14+P14+Q14+W14+X14 | AB14: =G14-AA14-L14-R14-Y14+U14-I14 | AC14: =AC13+AB14 | AD14: =M14+S14+Z14 | AE14: =J14+K14+O14+P14+V14+W14 | AF14: =AF13+AE14 | AG14: =IF(AD14<0.01,1,0)
A15: =DATE(YEAR(A14),MONTH(A14)+1,1) | B15: =IF(A15=Supuestos!$B$5,Supuestos!$B$7,Supuestos!$B$6) | C15: =IF(A15=Supuestos!$B$16,Supuestos!$B$15,0) | D15: =IF(A15=Supuestos!$B$5,Supuestos!$B$8,Supuestos!$B$43) | E15: =IF(AND(A15>Supuestos!$B$5,A15<=Supuestos!$B$12),Supuestos!$B$11,0) | F15: =IF(A15>=Supuestos!$B$14,Supuestos!$B$13,0) | G15: =B15+C15-D15-E15-F15 | H15: =M14 | I15: =MIN(U15,H15) | J15: =(H15-I15)*Supuestos!$B$46 | K15: =IF(H15-I15>0.01,MIN(Supuestos!$B$21,(H15-I15)*Supuestos!$B$20),0) | L15: =MIN(MAX(G15-AA15,0),H15-I15) | M15: =H15-I15-L15 | N15: =S14 | O15: =IF(A15=Supuestos!$B$5,0,N15*Supuestos!$B$47) | P15: =IF(AND(A15>Supuestos!$B$5,N15>0.01),Supuestos!$B$26,0) | Q15: =IF(A15=Supuestos!$B$5,0,MIN(Supuestos!$B$25,N15+O15)) | R15: =$B$4*MIN(MAX(G15-AA15-L15,0),N15+O15-Q15) | S15: =N15+O15-Q15-R15 | T15: =Z14 | U15: =IF(A15=Supuestos!$B$5,$B$3*Supuestos!$B$28,0) | V15: =T15*Supuestos!$B$48 | W15: =IF(T15>0.01,Supuestos!$B$58,0) | X15: =MIN(Supuestos!$B$57,T15+V15) | Y15: =$B$5*MIN(MAX(G15-AA15-L15-R15,0),T15+V15-X15) | Z15: =T15+U15+V15-X15-Y15 | AA15: =J15+K15+P15+Q15+W15+X15 | AB15: =G15-AA15-L15-R15-Y15+U15-I15 | AC15: =AC14+AB15 | AD15: =M15+S15+Z15 | AE15: =J15+K15+O15+P15+V15+W15 | AF15: =AF14+AE15 | AG15: =IF(AD15<0.01,1,0)
A16: =DATE(YEAR(A15),MONTH(A15)+1,1) | B16: =IF(A16=Supuestos!$B$5,Supuestos!$B$7,Supuestos!$B$6) | C16: =IF(A16=Supuestos!$B$16,Supuestos!$B$15,0) | D16: =IF(A16=Supuestos!$B$5,Supuestos!$B$8,Supuestos!$B$43) | E16: =IF(AND(A16>Supuestos!$B$5,A16<=Supuestos!$B$12),Supuestos!$B$11,0) | F16: =IF(A16>=Supuestos!$B$14,Supuestos!$B$13,0) | G16: =B16+C16-D16-E16-F16 | H16: =M15 | I16: =MIN(U16,H16) | J16: =(H16-I16)*Supuestos!$B$46 | K16: =IF(H16-I16>0.01,MIN(Supuestos!$B$21,(H16-I16)*Supuestos!$B$20),0) | L16: =MIN(MAX(G16-AA16,0),H16-I16) | M16: =H16-I16-L16 | N16: =S15 | O16: =IF(A16=Supuestos!$B$5,0,N16*Supuestos!$B$47) | P16: =IF(AND(A16>Supuestos!$B$5,N16>0.01),Supuestos!$B$26,0) | Q16: =IF(A16=Supuestos!$B$5,0,MIN(Supuestos!$B$25,N16+O16)) | R16: =$B$4*MIN(MAX(G16-AA16-L16,0),N16+O16-Q16) | S16: =N16+O16-Q16-R16 | T16: =Z15 | U16: =IF(A16=Supuestos!$B$5,$B$3*Supuestos!$B$28,0) | V16: =T16*Supuestos!$B$48 | W16: =IF(T16>0.01,Supuestos!$B$58,0) | X16: =MIN(Supuestos!$B$57,T16+V16) | Y16: =$B$5*MIN(MAX(G16-AA16-L16-R16,0),T16+V16-X16) | Z16: =T16+U16+V16-X16-Y16 | AA16: =J16+K16+P16+Q16+W16+X16 | AB16: =G16-AA16-L16-R16-Y16+U16-I16 | AC16: =AC15+AB16 | AD16: =M16+S16+Z16 | AE16: =J16+K16+O16+P16+V16+W16 | AF16: =AF15+AE16 | AG16: =IF(AD16<0.01,1,0)
A17: =DATE(YEAR(A16),MONTH(A16)+1,1) | B17: =IF(A17=Supuestos!$B$5,Supuestos!$B$7,Supuestos!$B$6) | C17: =IF(A17=Supuestos!$B$16,Supuestos!$B$15,0) | D17: =IF(A17=Supuestos!$B$5,Supuestos!$B$8,Supuestos!$B$43) | E17: =IF(AND(A17>Supuestos!$B$5,A17<=Supuestos!$B$12),Supuestos!$B$11,0) | F17: =IF(A17>=Supuestos!$B$14,Supuestos!$B$13,0) | G17: =B17+C17-D17-E17-F17 | H17: =M16 | I17: =MIN(U17,H17) | J17: =(H17-I17)*Supuestos!$B$46 | K17: =IF(H17-I17>0.01,MIN(Supuestos!$B$21,(H17-I17)*Supuestos!$B$20),0) | L17: =MIN(MAX(G17-AA17,0),H17-I17) | M17: =H17-I17-L17 | N17: =S16 | O17: =IF(A17=Supuestos!$B$5,0,N17*Supuestos!$B$47) | P17: =IF(AND(A17>Supuestos!$B$5,N17>0.01),Supuestos!$B$26,0) | Q17: =IF(A17=Supuestos!$B$5,0,MIN(Supuestos!$B$25,N17+O17)) | R17: =$B$4*MIN(MAX(G17-AA17-L17,0),N17+O17-Q17) | S17: =N17+O17-Q17-R17 | T17: =Z16 | U17: =IF(A17=Supuestos!$B$5,$B$3*Supuestos!$B$28,0) | V17: =T17*Supuestos!$B$48 | W17: =IF(T17>0.01,Supuestos!$B$58,0) | X17: =MIN(Supuestos!$B$57,T17+V17) | Y17: =$B$5*MIN(MAX(G17-AA17-L17-R17,0),T17+V17-X17) | Z17: =T17+U17+V17-X17-Y17 | AA17: =J17+K17+P17+Q17+W17+X17 | AB17: =G17-AA17-L17-R17-Y17+U17-I17 | AC17: =AC16+AB17 | AD17: =M17+S17+Z17 | AE17: =J17+K17+O17+P17+V17+W17 | AF17: =AF16+AE17 | AG17: =IF(AD17<0.01,1,0)
